Workbook
Name cpu_virtual_limite_superior: Outliers!$F$6
Name memoria_virtual_limite_superior: Outliers!$B$14
Name run_tradicional_limite_superior: Outliers!$C$6
Name memoria_tradicional_limite_inferior: Outliers!$C$13
Name run_virtual_limite_inferior: Outliers!$B$5
Name heap_tradicional_limite_superior: Outliers!$G$14
Name heap_tradicional_limite_inferior: Outliers!$G$13
Name run_virtual_limite_superior: Outliers!$B$6
Name cpu_tradicional_limite_superior: Outliers!$G$6
Name heap_virtual_limite_inferior: Outliers!$F$13
Name cpu_tradicional_limite_inferior: Outliers!$G$5
Name heap_virtual_limite_superior: Outliers!$F$14
Name memoria_virtual_limite_inferior: Outliers!$B$13
Name run_tradicional_limite_inferior: Outliers!$C$5
Name cpu_virtual_limite_inferior: Outliers!$F$5
Name memoria_tradicional_limite_superior: Outliers!$C$14

Sheet Dados
A1: run | B1: rate | C1: cpu | D1: memoria_gb | E1: heap_mb | F1: Outliers
A2: 2 | B2: 2400.1647 | C2: 0.025656128 | D2: 0.50835045 | E2: 229.24102 | F2: =IF(OR($B2>run_virtual_limite_superior, $B2<run_virtual_limite_inferior, $C2>cpu_virtual_limite_superior, $C2<cpu_virtual_limite_inferior,$D2<memoria_virtual_limite_inferior,$D2>memoria_virtual_limite_superior,E2>heap_virtual_limite_superior,E2<heap_virtual_limite_inferior), "OUTLIER", "OK") -> OK
A3: 4 | B3: 2198.8331 | C3: 0.023543883 | D3: 0.80881296 | E3: 273.4698 | F3: =IF(OR($B3>run_virtual_limite_superior, $B3<run_virtual_limite_inferior, $C3>cpu_virtual_limite_superior, $C3<cpu_virtual_limite_inferior,$D3<memoria_virtual_limite_inferior,$D3>memoria_virtual_limite_superior,E3>heap_virtual_limite_superior,E3<heap_virtual_limite_inferior), "OUTLIER", "OK") -> OUTLIER
A4: 6 | B4: 3050.1524 | C4: 0.029379472 | D4: 0.53785483 | E4: 265.49738 | F4: =IF(OR($B4>run_virtual_limite_superior, $B4<run_virtual_limite_inferior, $C4>cpu_virtual_limite_superior, $C4<cpu_virtual_limite_inferior,$D4<memoria_virtual_limite_inferior,$D4>memoria_virtual_limite_superior,E4>heap_virtual_limite_superior,E4<heap_virtual_limite_inferior), "OUTLIER", "OK") -> OK
A5: 8 | B5: 2812.3895 | C5: 0.029001069 | D5: 0.52042556 | E5: 241.17149 | F5: =IF(OR($B5>run_virtual_limite_superior, $B5<run_virtual_limite_inferior, $C5>cpu_virtual_limite_superior, $C5<cpu_virtual_limite_inferior,$D5<memoria_virtual_limite_inferior,$D5>memoria_virtual_limite_superior,E5>heap_virtual_limite_superior,E5<heap_virtual_limite_inferior), "OUTLIER", "OK") -> OK
A6: 10 | B6: 4394.1567 | C6: 0.041815972 | D6: 0.48995487 | E6: 227.25707 | F6: =IF(OR($B6>run_virtual_limite_superior, $B6<run_virtual_limite_inferior, $C6>cpu_virtual_limite_superior, $C6<cpu_virtual_limite_inferior,$D6<memoria_virtual_limite_inferior,$D6>memoria_virtual_limite_superior,E6>heap_virtual_limite_superior,E6<heap_virtual_limite_inferior), "OUTLIER", "OK") -> OUTLIER
A7: 12 | B7: 3050.0349 | C7: 0.028923534 | D7: 0.6145716 | E7: 290.22913 | F7: =IF(OR($B7>run_virtual_limite_superior, $B7<run_virtual_limite_inferior, $C7>cpu_virtual_limite_superior, $C7<cpu_virtual_limite_inferior,$D7<memoria_virtual_limite_inferior,$D7>memoria_virtual_limite_superior,E7>heap_virtual_limite_superior,E7<heap_virtual_limite_inferior), "OUTLIER", "OK") -> OUTLIER
A8: 14 | B8: 4800.0619 | C8: 0.044098666 | D8: 0.51952926 | E8: 243.44977 | F8: =IF(OR($B8>run_virtual_limite_superior, $B8<run_virtual_limite_inferior, $C8>cpu_virtual_limite_superior, $C8<cpu_virtual_limite_inferior,$D8<memoria_virtual_limite_inferior,$D8>memoria_virtual_limite_superior,E8>heap_virtual_limite_superior,E8<heap_virtual_limite_inferior), "OUTLIER", "OK") -> OUTLIER
A9: 16 | B9: 2900.2166 | C9: 0.03050124 | D9: 0.61591979 | E9: 268.52277 | F9: =IF(OR($B9>run_virtual_limite_superior, $B9<run_virtual_limite_inferior, $C9>cpu_virtual_limite_superior, $C9<cpu_virtual_limite_inferior,$D9<memoria_virtual_limite_inferior,$D9>memoria_virtual_limite_superior,E9>heap_virtual_limite_superior,E9<heap_virtual_limite_inferior), "OUTLIER", "OK") -> OUTLIER
A10: 18 | B10: 2300.1182 | C10: 0.025134377 | D10: 0.49394476 | E10: 201.79297 | F10: =IF(OR($B10>run_virtual_limite_superior, $B10<run_virtual_limite_inferior, $C10>cpu_virtual_limite_superior, $C10<cpu_virtual_limite_inferior,$D10<memoria_virtual_limite_inferior,$D10>memoria_virtual_limite_superior,E10>heap_virtual_limite_superior,E10<heap_virtual_limite_inferior), "OUTLIER", "OK") -> OK
A11: 20 | B11: 2500.2908 | C11: 0.026718798 | D11: 0.44644387 | E11: 187.15487 | F11: =IF(OR($B11>run_virtual_limite_superior, $B11<run_virtual_limite_inferior, $C11>cpu_virtual_limite_superior, $C11<cpu_virtual_limite_inferior,$D11<memoria_virtual_limite_inferior,$D11>memoria_virtual_limite_superior,E11>heap_virtual_limite_superior,E11<heap_virtual_limite_inferior), "OUTLIER", "OK") -> OK
A12: 22 | B12: 2650.2599 | C12: 0.027042031 | D12: 0.52109711 | E12: 215.07968 | F12: =IF(OR($B12>run_virtual_limite_superior, $B12<run_virtual_limite_inferior, $C12>cpu_virtual_limite_superior, $C12<cpu_virtual_limite_inferior,$D12<memoria_virtual_limite_inferior,$D12>memoria_virtual_limite_superior,E12>heap_virtual_limite_superior,E12<heap_virtual_limite_inferior), "OUTLIER", "OK") -> OK
A13: 24 | B13: 1699.9986 | C13: 0.020078535 | D13: 0.54624878 | E13: 223.65709 | F13: =IF(OR($B13>run_virtual_limite_superior, $B13<run_virtual_limite_inferior, $C13>cpu_virtual_limite_superior, $C13<cpu_virtual_limite_inferior,$D13<memoria_virtual_limite_inferior,$D13>memoria_virtual_limite_superior,E13>heap_virtual_limite_superior,E13<heap_virtual_limite_inferior), "OUTLIER", "OK") -> OK
... A31: 60 | B31: 900.03746 | C31: 0.013116195 | D31: 0.44769111 | E31: 164.58935 | F31: =IF(OR($B31>run_virtual_limite_superior, $B31<run_virtual_limite_inferior, $C31>cpu_virtual_limite_superior, $C31<cpu_virtual_limite_inferior,$D31<memoria_virtual_limite_inferior,$D31>memoria_virtual_limite_superior,E31>heap_virtual_limite_superior,E31<heap_virtual_limite_inferior), "OUTLIER", "OK") -> OK
A32: 62 | B32: 800.14159 | C32: 0.0029810589 | D32: 0.21541946 | E32: 41.686623 | F32: =IF(OR($B76>run_virtual_limite_superior, $B76<run_virtual_limite_inferior, $C32>cpu_virtual_limite_superior, $C32<cpu_virtual_limite_inferior,$D32<memoria_virtual_limite_inferior,$D32>memoria_virtual_limite_superior,E32>heap_virtual_limite_superior,E32<heap_virtual_limite_inferior), "OUTLIER", "OK") -> OUTLIER
A33: 64 | B33: 4549.8774 | C33: 0.044058125 | D33: 0.50474712 | E33: 228.25117 | F33: =IF(OR($B33>run_virtual_limite_superior, $B33<run_virtual_limite_inferior, $C33>cpu_virtual_limite_superior, $C33<cpu_virtual_limite_inferior,$D33<memoria_virtual_limite_inferior,$D33>memoria_virtual_limite_superior,E33>heap_virtual_limite_superior,E33<heap_virtual_limite_inferior), "OUTLIER", "OK") -> OUTLIER
A34: 66 | B34: 2800.0886 | C34: 0.028344725 | D34: 0.47312459 | E34: 213.36385 | F34: =IF(OR($B34>run_virtual_limite_superior, $B34<run_virtual_limite_inferior, $C34>cpu_virtual_limite_superior, $C34<cpu_virtual_limite_inferior,$D34<memoria_virtual_limite_inferior,$D34>memoria_virtual_limite_superior,E34>heap_virtual_limite_superior,E34<heap_virtual_limite_inferior), "OUTLIER", "OK") -> OK
A35: 68 | B35: 2586.0056 | C35: 0.027489732 | D35: 0.52965991 | E35: 242.4596 | F35: =IF(OR($B35>run_virtual_limite_superior, $B35<run_virtual_limite_inferior, $C35>cpu_virtual_limite_superior, $C35<cpu_virtual_limite_inferior,$D35<memoria_virtual_limite_inferior,$D35>memoria_virtual_limite_superior,E35>heap_virtual_limite_superior,E35<heap_virtual_limite_inferior), "OUTLIER", "OK") -> OK
A36: 70 | B36: 1000.0556 | C36: 0.015394881 | D36: 0.25730218 | E36: 73.374791 | F36: =IF(OR($B36>run_virtual_limite_superior, $B36<run_virtual_limite_inferior, $C36>cpu_virtual_limite_superior, $C36<cpu_virtual_limite_inferior,$D36<memoria_virtual_limite_inferior,$D36>memoria_virtual_limite_superior,E36>heap_virtual_limite_superior,E36<heap_virtual_limite_inferior), "OUTLIER", "OK") -> OUTLIER
A37: 72 | B37: 2550.0143 | C37: 0.025342862 | D37: 0.45305919 | E37: 206.2965 | F37: =IF(OR($B37>run_virtual_limite_superior, $B37<run_virtual_limite_inferior, $C37>cpu_virtual_limite_superior, $C37<cpu_virtual_limite_inferior,$D37<memoria_virtual_limite_inferior,$D37>memoria_virtual_limite_superior,E37>heap_virtual_limite_superior,E37<heap_virtual_limite_inferior), "OUTLIER", "OK") -> OK
A38: 74 | B38: 1500.0691 | C38: 0.018627201 | D38: 0.56719302 | E38: 183.31359 | F38: =IF(OR($B38>run_virtual_limite_superior, $B38<run_virtual_limite_inferior, $C38>cpu_virtual_limite_superior, $C38<cpu_virtual_limite_inferior,$D38<memoria_virtual_limite_inferior,$D38>memoria_virtual_limite_superior,E38>heap_virtual_limite_superior,E38<heap_virtual_limite_inferior), "OUTLIER", "OK") -> OK
A39: 76 | B39: 3179.3958 | C39: 0.030621917 | D39: 0.64927074 | E39: 267.75398 | F39: =IF(OR($B39>run_virtual_limite_superior, $B39<run_virtual_limite_inferior, $C39>cpu_virtual_limite_superior, $C39<cpu_virtual_limite_inferior,$D39<memoria_virtual_limite_inferior,$D39>memoria_virtual_limite_superior,E39>heap_virtual_limite_superior,E39<heap_virtual_limite_inferior), "OUTLIER", "OK") -> OUTLIER
A40: 78 | B40: 1700.0051 | C40: 0.020844196 | D40: 0.54043253 | E40: 210.14338 | F40: =IF(OR($B40>run_virtual_limite_superior, $B40<run_virtual_limite_inferior, $C40>cpu_virtual_limite_superior, $C40<cpu_virtual_limite_inferior,$D40<memoria_virtual_limite_inferior,$D40>memoria_virtual_limite_superior,E40>heap_virtual_limite_superior,E40<heap_virtual_limite_inferior), "OUTLIER", "OK") -> OK
A41: 80 | B41: 4849.6982 | C41: 0.044616423 | D41: 0.54068558 | E41: 233.20108 | F41: =IF(OR($B41>run_virtual_limite_superior, $B41<run_virtual_limite_inferior, $C41>cpu_virtual_limite_superior, $C41<cpu_virtual_limite_inferior,$D41<memoria_virtual_limite_inferior,$D41>memoria_virtual_limite_superior,E41>heap_virtual_limite_superior,E41<heap_virtual_limite_inferior), "OUTLIER", "OK") -> OUTLIER
A42: 82 | B42: 3200.0669 | C42: 0.033152156 | D42: 0.51092847 | E42: 202.88504 | F42: =IF(OR($B42>run_virtual_limite_superior, $B42<run_virtual_limite_inferior, $C42>cpu_virtual_limite_superior, $C42<cpu_virtual_limite_inferior,$D42<memoria_virtual_limite_inferior,$D42>memoria_virtual_limite_superior,E42>heap_virtual_limite_superior,E42<heap_virtual_limite_inferior), "OUTLIER", "OK") -> OK
A43: 84 | B43: 2250.0936 | C43: 0.023621536 | D43: 0.82700507 | E43: 298.66084 | F43: =IF(OR($B43>run_virtual_limite_superior, $B43<run_virtual_limite_inferior, $C43>cpu_virtual_limite_superior, $C43<cpu_virtual_limite_inferior,$D43<memoria_virtual_limite_inferior,$D43>memoria_virtual_limite_superior,E43>heap_virtual_limite_superior,E43<heap_virtual_limite_inferior), "OUTLIER", "OK") -> OUTLIER
A44: 86 | B44: 1099.9296 | C44: 0.015244711 | D44: 0.48072032 | E44: 147.27827 | F44: =IF(OR($B44>run_virtual_limite_superior, $B44<run_virtual_limite_inferior, $C44>cpu_virtual_limite_superior, $C44<cpu_virtual_limite_inferior,$D44<memoria_virtual_limite_inferior,$D44>memoria_virtual_limite_superior,E44>heap_virtual_limite_superior,E44<heap_virtual_limite_inferior), "OUTLIER", "OK") -> OK
... A51: 100 | B51: 1798.9634 | C51: 0.021064186 | D51: 0.474032 | E51: 187.79134 | F51: =IF(OR($B51>run_virtual_limite_superior, $B51<run_virtual_limite_inferior, $C51>cpu_virtual_limite_superior, $C51<cpu_virtual_limite_inferior,$D51<memoria_virtual_limite_inferior,$D51>memoria_virtual_limite_superior,E51>heap_virtual_limite_superior,E51<heap_virtual_limite_inferior), "OUTLIER", "OK") -> OK
A54: run | B54: rate | C54: cpu | D54: memoria_gb | E54: heap_mb | F54: Outliers
A55: 1 | B55: 2399.925 | C55: 0.042268418 | D55: 0.69655038 | E55: 289.40568 | F55: =IF(OR($B55>run_tradicional_limite_superior, $B55<run_tradicional_limite_inferior,$C55>cpu_tradicional_limite_superior, $C55<cpu_tradicional_limite_inferior,$D55>memoria_tradicional_limite_superior,$D55<memoria_tradicional_limite_inferior,$E55>heap_tradicional_limite_superior,$E55<heap_tradicional_limite_inferior),"OUTLIER", "OK") -> OUTLIER
A56: 3 | B56: 2700.1081 | C56: 0.047848371 | D56: 0.58640956 | E56: 272.4987 | F56: =IF(OR($B56>run_tradicional_limite_superior, $B56<run_tradicional_limite_inferior,$C56>cpu_tradicional_limite_superior, $C56<cpu_tradicional_limite_inferior,$D56>memoria_tradicional_limite_superior,$D56<memoria_tradicional_limite_inferior,$E56>heap_tradicional_limite_superior,$E56<heap_tradicional_limite_inferior),"OUTLIER", "OK") -> OK
A57: 5 | B57: 2250.1038 | C57: 0.043554261 | D57: 0.75464585 | E57: 312.88395 | F57: =IF(OR($B57>run_tradicional_limite_superior, $B57<run_tradicional_limite_inferior,$C57>cpu_tradicional_limite_superior, $C57<cpu_tradicional_limite_inferior,$D57>memoria_tradicional_limite_superior,$D57<memoria_tradicional_limite_inferior,$E57>heap_tradicional_limite_superior,$E57<heap_tradicional_limite_inferior),"OUTLIER", "OK") -> OUTLIER
A58: 7 | B58: 1750.0878 | C58: 0.035630226 | D58: 0.4525276 | E58: 187.08297 | F58: =IF(OR($B58>run_tradicional_limite_superior, $B58<run_tradicional_limite_inferior,$C58>cpu_tradicional_limite_superior, $C58<cpu_tradicional_limite_inferior,$D58>memoria_tradicional_limite_superior,$D58<memoria_tradicional_limite_inferior,$E58>heap_tradicional_limite_superior,$E58<heap_tradicional_limite_inferior),"OUTLIER", "OK") -> OK
A59: 9 | B59: 1800.0681 | C59: 0.04098438 | D59: 0.43363417 | E59: 168.08036 | F59: =IF(OR($B59>run_tradicional_limite_superior, $B59<run_tradicional_limite_inferior,$C59>cpu_tradicional_limite_superior, $C59<cpu_tradicional_limite_inferior,$D59>memoria_tradicional_limite_superior,$D59<memoria_tradicional_limite_inferior,$E59>heap_tradicional_limite_superior,$E59<heap_tradicional_limite_inferior),"OUTLIER", "OK") -> OK
A60: 11 | B60: 1249.5673 | C60: 0.027408578 | D60: 0.36682326 | E60: 132.4826 | F60: =IF(OR($B60>run_tradicional_limite_superior, $B60<run_tradicional_limite_inferior,$C60>cpu_tradicional_limite_superior, $C60<cpu_tradicional_limite_inferior,$D60>memoria_tradicional_limite_superior,$D60<memoria_tradicional_limite_inferior,$E60>heap_tradicional_limite_superior,$E60<heap_tradicional_limite_inferior),"OUTLIER", "OK") -> OK
A61: 13 | B61: 3150.0966 | C61: 0.056326026 | D61: 0.52800351 | E61: 257.61831 | F61: =IF(OR($B61>run_tradicional_limite_superior, $B61<run_tradicional_limite_inferior,$C61>cpu_tradicional_limite_superior, $C61<cpu_tradicional_limite_inferior,$D61>memoria_tradicional_limite_superior,$D61<memoria_tradicional_limite_inferior,$E61>heap_tradicional_limite_superior,$E61<heap_tradicional_limite_inferior),"OUTLIER", "OK") -> OK
A62: 15 | B62: 4000.019 | C62: 0.067462002 | D62: 0.4713789 | E62: 206.24587 | F62: =IF(OR($B62>run_tradicional_limite_superior, $B62<run_tradicional_limite_inferior,$C62>cpu_tradicional_limite_superior, $C62<cpu_tradicional_limite_inferior,$D62>memoria_tradicional_limite_superior,$D62<memoria_tradicional_limite_inferior,$E62>heap_tradicional_limite_superior,$E62<heap_tradicional_limite_inferior),"OUTLIER", "OK") -> OUTLIER
A63: 17 | B63: 2716.4362 | C63: 0.055481783 | D63: 0.58791516 | E63: 241.63731 | F63: =IF(OR($B63>run_tradicional_limite_superior, $B63<run_tradicional_limite_inferior,$C63>cpu_tradicional_limite_superior, $C63<cpu_tradicional_limite_inferior,$D63>memoria_tradicional_limite_superior,$D63<memoria_tradicional_limite_inferior,$E63>heap_tradicional_limite_superior,$E63<heap_tradicional_limite_inferior),"OUTLIER", "OK") -> OK
A64: 19 | B64: 1497.9308 | C64: 0.032048068 | D64: 0.43311624 | E64: 178.51521 | F64: =IF(OR($B64>run_tradicional_limite_superior, $B64<run_tradicional_limite_inferior,$C64>cpu_tradicional_limite_superior, $C64<cpu_tradicional_limite_inferior,$D64>memoria_tradicional_limite_superior,$D64<memoria_tradicional_limite_inferior,$E64>heap_tradicional_limite_superior,$E64<heap_tradicional_limite_inferior),"OUTLIER", "OK") -> OK
A65: 21 | B65: 899.15998 | C65: 0.022374436 | D65: 0.54399645 | E65: 215.61972 | F65: =IF(OR($B65>run_tradicional_limite_superior, $B65<run_tradicional_limite_inferior,$C65>cpu_tradicional_limite_superior, $C65<cpu_tradicional_limite_inferior,$D65>memoria_tradicional_limite_superior,$D65<memoria_tradicional_limite_inferior,$E65>heap_tradicional_limite_superior,$E65<heap_tradicional_limite_inferior),"OUTLIER", "OK") -> OK
...

Sheet Outliers
A1: Métrica | B1: virtual | C1: tradicional | E1: Métrica | F1: virtual | G1: tradicional
A2: Q1 | B2: =QUARTILE(Virtual[rate], 1) -> 1700.0002 | C2: =QUARTILE(Tradicional[rate], 1) -> 1411.1599 | E2: Q1 | F2: =QUARTILE(Virtual[cpu], 1) -> 0.01932348 | G2: =QUARTILE(Tradicional[cpu], 1) -> 0.032064113
A3: Q3 | B3: =QUARTILE(Virtual[rate], 3) -> 3050.123 | C3: =QUARTILE(Tradicional[rate], 3) -> 3081.4629 | E3: Q3 | F3: =QUARTILE(Virtual[cpu], 3) -> 0.030257325 | G3: =QUARTILE(Tradicional[cpu], 3) -> 0.055559693
A4: IQR | B4: =B3 - B2 -> 1350.1228 | C4: =C3 - C2 -> 1670.303 | E4: IQR | F4: =F3 - F2 -> 0.010933845 | G4: =G3 - G2 -> 0.02349558
A5: Limite inferior | B5: =B2 - 1.5 * B4 -> -325.18397 | C5: =C2 - 1.5 * C4 -> -1094.2946 | E5: Limite inferior | F5: =F2 - 1.5 * F4 -> 0.0029227122 | G5: =G2 - 1.5 * G4 -> -0.0031792573
A6: Limite superior | B6: =B2 + 1.5 * B4 -> 3725.1844 | C6: =C2 + 1.5 * C4 -> 3916.6144 | E6: Limite superior | F6: =F2 + 1.5 * F4 -> 0.035724248 | G6: =G2 + 1.5 * G4 -> 0.067307483
A9: Métrica | B9: virtual | C9: tradicional | E9: Métrica | F9: virtual | G9: tradicional
A10: Q1 | B10: =QUARTILE(Virtual[memoria_gb], 1) -> 0.44675568 | C10: =QUARTILE(Tradicional[memoria_gb], 1) -> 0.43121838 | E10: Q1 | F10: =QUARTILE(Virtual[heap_mb], 1) -> 165.25842 | G10: =QUARTILE(Tradicional[heap_mb], 1) -> 167.27253
A11: Q3 | B11: =QUARTILE(Virtual[memoria_gb], 3) -> 0.55469706 | C11: =QUARTILE(Tradicional[memoria_gb], 3) -> 0.57302118 | E11: Q3 | F11: =QUARTILE(Virtual[heap_mb], 3) -> 240.02391 | G11: =QUARTILE(Tradicional[heap_mb], 3) -> 254.30748
A12: IQR | B12: =B11 - B10 -> 0.10794139 | C12: =C11 - C10 -> 0.1418028 | E12: IQR | F12: =F11 - F10 -> 74.765489 | G12: =G11 - G10 -> 87.034951
A13: Limite inferior | B13: =B10 - 1.5 * B12 -> 0.2848436 | C13: =C10 - 1.5 * C12 -> 0.21851418 | E13: Limite inferior | F13: =F10 - 1.5 * F12 -> 53.110185 | G13: =G10 - 1.5 * G12 -> 36.720099
A14: Limite superior | B14: =B10 + 1.5 * B12 -> 0.60866776 | C14: =C10 + 1.5 * C12 -> 0.64392258 | E14: Limite superior | F14: =F10 + 1.5 * F12 -> 277.40665 | G14: =G10 + 1.5 * G12 -> 297.82495

Sheet Dados_sem_outliers
A1: run | B1: rate | C1: cpu | D1: memoria_gb | E1: heap_mb
A2: =IFERROR(__xludf.DUMMYFUNCTION("FILTER(Virtual[[run]:[heap_mb]], Virtual[Outliers]=""OK"") "),2.0) -> 2 | B2: =IFERROR(__xludf.DUMMYFUNCTION("""COMPUTED_VALUE"""),2400.16473961087) -> 2400.1647 | C2: =IFERROR(__xludf.DUMMYFUNCTION("""COMPUTED_VALUE"""),0.025656128152627) -> 0.025656128 | D2: =IFERROR(__xludf.DUMMYFUNCTION("""COMPUTED_VALUE"""),0.508350453133825) -> 0.50835045 | E2: =IFERROR(__xludf.DUMMYFUNCTION("""COMPUTED_VALUE"""),229.241020242167) -> 229.24102
A3: =IFERROR(__xludf.DUMMYFUNCTION("""COMPUTED_VALUE"""),6.0) -> 6 | B3: =IFERROR(__xludf.DUMMYFUNCTION("""COMPUTED_VALUE"""),3050.15242024378) -> 3050.1524 | C3: =IFERROR(__xludf.DUMMYFUNCTION("""COMPUTED_VALUE"""),0.0293794720736326) -> 0.029379472 | D3: =IFERROR(__xludf.DUMMYFUNCTION("""COMPUTED_VALUE"""),0.537854833970683) -> 0.53785483 | E3: =IFERROR(__xludf.DUMMYFUNCTION("""COMPUTED_VALUE"""),265.497382822344) -> 265.49738
A4: =IFERROR(__xludf.DUMMYFUNCTION("""COMPUTED_VALUE"""),8.0) -> 8 | B4: =IFERROR(__xludf.DUMMYFUNCTION("""COMPUTED_VALUE"""),2812.38945663305) -> 2812.3895 | C4: =IFERROR(__xludf.DUMMYFUNCTION("""COMPUTED_VALUE"""),0.029001068779167) -> 0.029001069 | D4: =IFERROR(__xludf.DUMMYFUNCTION("""COMPUTED_VALUE"""),0.520425557474043) -> 0.52042556 | E4: =IFERROR(__xludf.DUMMYFUNCTION("""COMPUTED_VALUE"""),241.171490366496) -> 241.17149
A5: =IFERROR(__xludf.DUMMYFUNCTION("""COMPUTED_VALUE"""),18.0) -> 18 | B5: =IFERROR(__xludf.DUMMYFUNCTION("""COMPUTED_VALUE"""),2300.11816811086) -> 2300.1182 | C5: =IFERROR(__xludf.DUMMYFUNCTION("""COMPUTED_VALUE"""),0.0251343773043789) -> 0.025134377 | D5: =IFERROR(__xludf.DUMMYFUNCTION("""COMPUTED_VALUE"""),0.493944756528561) -> 0.49394476 | E5: =IFERROR(__xludf.DUMMYFUNCTION("""COMPUTED_VALUE"""),201.792971486058) -> 201.79297
A6: =IFERROR(__xludf.DUMMYFUNCTION("""COMPUTED_VALUE"""),20.0) -> 20 | B6: =IFERROR(__xludf.DUMMYFUNCTION("""COMPUTED_VALUE"""),2500.29083833083) -> 2500.2908 | C6: =IFERROR(__xludf.DUMMYFUNCTION("""COMPUTED_VALUE"""),0.0267187975017545) -> 0.026718797 | D6: =IFERROR(__xludf.DUMMYFUNCTION("""COMPUTED_VALUE"""),0.446443866000277) -> 0.44644387 | E6: =IFERROR(__xludf.DUMMYFUNCTION("""COMPUTED_VALUE"""),187.154872573049) -> 187.15487
A7: =IFERROR(__xludf.DUMMYFUNCTION("""COMPUTED_VALUE"""),22.0) -> 22 | B7: =IFERROR(__xludf.DUMMYFUNCTION("""COMPUTED_VALUE"""),2650.2598658009) -> 2650.2599 | C7: =IFERROR(__xludf.DUMMYFUNCTION("""COMPUTED_VALUE"""),0.0270420309235981) -> 0.027042031 | D7: =IFERROR(__xludf.DUMMYFUNCTION("""COMPUTED_VALUE"""),0.521097106766393) -> 0.52109711 | E7: =IFERROR(__xludf.DUMMYFUNCTION("""COMPUTED_VALUE"""),215.079676553874) -> 215.07968
A8: =IFERROR(__xludf.DUMMYFUNCTION("""COMPUTED_VALUE"""),24.0) -> 24 | B8: =IFERROR(__xludf.DUMMYFUNCTION("""COMPUTED_VALUE"""),1699.99859646091) -> 1699.9986 | C8: =IFERROR(__xludf.DUMMYFUNCTION("""COMPUTED_VALUE"""),0.0200785352288945) -> 0.020078535 | D8: =IFERROR(__xludf.DUMMYFUNCTION("""COMPUTED_VALUE"""),0.546248776573011) -> 0.54624878 | E8: =IFERROR(__xludf.DUMMYFUNCTION("""COMPUTED_VALUE"""),223.657092935898) -> 223.65709
A9: =IFERROR(__xludf.DUMMYFUNCTION("""COMPUTED_VALUE"""),26.0) -> 26 | B9: =IFERROR(__xludf.DUMMYFUNCTION("""COMPUTED_VALUE"""),2172.14604163253) -> 2172.146 | C9: =IFERROR(__xludf.DUMMYFUNCTION("""COMPUTED_VALUE"""),0.0190717950586729) -> 0.019071795 | D9: =IFERROR(__xludf.DUMMYFUNCTION("""COMPUTED_VALUE"""),0.519338865617576) -> 0.51933887 | E9: =IFERROR(__xludf.DUMMYFUNCTION("""COMPUTED_VALUE"""),198.497380894938) -> 198.49738
A10: =IFERROR(__xludf.DUMMYFUNCTION("""COMPUTED_VALUE"""),28.0) -> 28 | B10: =IFERROR(__xludf.DUMMYFUNCTION("""COMPUTED_VALUE"""),2150.12610726132) -> 2150.1261 | C10: =IFERROR(__xludf.DUMMYFUNCTION("""COMPUTED_VALUE"""),0.0223563316002524) -> 0.022356332 | D10: =IFERROR(__xludf.DUMMYFUNCTION("""COMPUTED_VALUE"""),0.571959598085633) -> 0.5719596 | E10: =IFERROR(__xludf.DUMMYFUNCTION("""COMPUTED_VALUE"""),252.335015787661) -> 252.33502
A11: =IFERROR(__xludf.DUMMYFUNCTION("""COMPUTED_VALUE"""),32.0) -> 32 | B11: =IFERROR(__xludf.DUMMYFUNCTION("""COMPUTED_VALUE"""),2450.16662933069) -> 2450.1666 | C11: =IFERROR(__xludf.DUMMYFUNCTION("""COMPUTED_VALUE"""),0.0247793398313917) -> 0.02477934 | D11: =IFERROR(__xludf.DUMMYFUNCTION("""COMPUTED_VALUE"""),0.473920258222699) -> 0.47392026 | E11: =IFERROR(__xludf.DUMMYFUNCTION("""COMPUTED_VALUE"""),192.051260948181) -> 192.05126
A12: =IFERROR(__xludf.DUMMYFUNCTION("""COMPUTED_VALUE"""),34.0) -> 34 | B12: =IFERROR(__xludf.DUMMYFUNCTION("""COMPUTED_VALUE"""),1800.1838156893) -> 1800.1838 | C12: =IFERROR(__xludf.DUMMYFUNCTION("""COMPUTED_VALUE"""),0.0224766231504992) -> 0.022476623 | D12: =IFERROR(__xludf.DUMMYFUNCTION("""COMPUTED_VALUE"""),0.397349001098981) -> 0.397349 | E12: =IFERROR(__xludf.DUMMYFUNCTION("""COMPUTED_VALUE"""),152.48830452261) -> 152.4883
A13: =IFERROR(__xludf.DUMMYFUNCTION("""COMPUTED_VALUE"""),38.0) -> 38 | B13: =IFERROR(__xludf.DUMMYFUNCTION("""COMPUTED_VALUE"""),600.086387116099) -> 600.08639 | C13: =IFERROR(__xludf.DUMMYFUNCTION("""COMPUTED_VALUE"""),0.0106875234192356) -> 0.010687523 | D13: =IFERROR(__xludf.DUMMYFUNCTION("""COMPUTED_VALUE"""),0.309908093782895) -> 0.30990809 | E13: =IFERROR(__xludf.DUMMYFUNCTION("""COMPUTED_VALUE"""),88.4348994168368) -> 88.434899
A14: =IFERROR(__xludf.DUMMYFUNCTION("""COMPUTED_VALUE"""),40.0) -> 40 | B14: =IFERROR(__xludf.DUMMYFUNCTION("""COMPUTED_VALUE"""),2350.03479085505) -> 2350.0348 | C14: =IFERROR(__xludf.DUMMYFUNCTION("""COMPUTED_VALUE"""),0.0259291709567248) -> 0.025929171 | D14: =IFERROR(__xludf.DUMMYFUNCTION("""COMPUTED_VALUE"""),0.417729913802474) -> 0.41772991 | E14: =IFERROR(__xludf.DUMMYFUNCTION("""COMPUTED_VALUE"""),170.025393410616) -> 170.02539
A15: =IFERROR(__xludf.DUMMYFUNCTION("""COMPUTED_VALUE"""),42.0) -> 42 | B15: =IFERROR(__xludf.DUMMYFUNCTION("""COMPUTED_VALUE"""),950.045347944566) -> 950.04535 | C15: =IFERROR(__xludf.DUMMYFUNCTION("""COMPUTED_VALUE"""),0.0118003265054372) -> 0.011800327 | D15: =IFERROR(__xludf.DUMMYFUNCTION("""COMPUTED_VALUE"""),0.381309262572125) -> 0.38130926 | E15: =IFERROR(__xludf.DUMMYFUNCTION("""COMPUTED_VALUE"""),107.084897677103) -> 107.0849
A16: =IFERROR(__xludf.DUMMYFUNCTION("""COMPUTED_VALUE"""),44.0) -> 44 | B16: =IFERROR(__xludf.DUMMYFUNCTION("""COMPUTED_VALUE"""),2200.26896439863) -> 2200.269 | C16: =IFERROR(__xludf.DUMMYFUNCTION("""COMPUTED_VALUE"""),0.0244347434051494) -> 0.024434743 | D16: =IFERROR(__xludf.DUMMYFUNCTION("""COMPUTED_VALUE"""),0.526020050136818) -> 0.52602005 | E16: =IFERROR(__xludf.DUMMYFUNCTION("""COMPUTED_VALUE"""),228.724038511514) -> 228.72404
A17: =IFERROR(__xludf.DUMMYFUNCTION("""COMPUTED_VALUE"""),48.0) -> 48 | B17: =IFERROR(__xludf.DUMMYFUNCTION("""COMPUTED_VALUE"""),3242.485630248) -> 3242.4856 | C17: =IFERROR(__xludf.DUMMYFUNCTION("""COMPUTED_VALUE"""),0.0353024544027993) -> 0.035302454 | D17: =IFERROR(__xludf.DUMMYFUNCTION("""COMPUTED_VALUE"""),0.397113614581402) -> 0.39711361 | E17: =IFERROR(__xludf.DUMMYFUNCTION("""COMPUTED_VALUE"""),166.943810545122) -> 166.94381
A18: =IFERROR(__xludf.DUMMYFUNCTION("""COMPUTED_VALUE"""),52.0) -> 52 | B18: =IFERROR(__xludf.DUMMYFUNCTION("""COMPUTED_VALUE"""),2913.73602541652) -> 2913.736 | C18: =IFERROR(__xludf.DUMMYFUNCTION("""COMPUTED_VALUE"""),0.0295255827923833) -> 0.029525583 | D18: =IFERROR(__xludf.DUMMYFUNCTION("""COMPUTED_VALUE"""),0.55751315847685) -> 0.55751316 | E18: =IFERROR(__xludf.DUMMYFUNCTION("""COMPUTED_VALUE"""),240.243834665843) -> 240.24383
A19: =IFERROR(__xludf.DUMMYFUNCTION("""COMPUTED_VALUE"""),54.0) -> 54 | B19: =IFERROR(__xludf.DUMMYFUNCTION("""COMPUTED_VALUE"""),1046.37571706949) -> 1046.3757 | C19: =IFERROR(__xludf.DUMMYFUNCTION("""COMPUTED_VALUE"""),0.0137317561344874) -> 0.013731756 | D19: =IFERROR(__xludf.DUMMYFUNCTION("""COMPUTED_VALUE"""),0.513412102459831) -> 0.5134121 | E19: =IFERROR(__xludf.DUMMYFUNCTION("""COMPUTED_VALUE"""),153.706406649421) -> 153.70641
A20: =IFERROR(__xludf.DUMMYFUNCTION("""COMPUTED_VALUE"""),56.0) -> 56 | B20: =IFERROR(__xludf.DUMMYFUNCTION("""COMPUTED_VALUE"""),3450.39516720274) -> 3450.3952 | C20: =IFERROR(__xludf.DUMMYFUNCTION("""COMPUTED_VALUE"""),0.0357094974959824) -> 0.035709497 | D20: =IFERROR(__xludf.DUMMYFUNCTION("""COMPUTED_VALUE"""),0.425386677378553) -> 0.42538668 | E20: =IFERROR(__xludf.DUMMYFUNCTION("""COMPUTED_VALUE"""),164.555750285877) -> 164.55575
A21: =IFERROR(__xludf.DUMMYFUNCTION("""COMPUTED_VALUE"""),58.0) -> 58 | B21: =IFERROR(__xludf.DUMMYFUNCTION("""COMPUTED_VALUE"""),1450.07016193479) -> 1450.0702 | C21: =IFERROR(__xludf.DUMMYFUNCTION("""COMPUTED_VALUE"""),0.0158830499867483) -> 0.01588305 | D21: =IFERROR(__xludf.DUMMYFUNCTION("""COMPUTED_VALUE"""),0.315501424357187) -> 0.31550142 | E21: =IFERROR(__xludf.DUMMYFUNCTION("""COMPUTED_VALUE"""),100.282444055529) -> 100.28244
A22: =IFERROR(__xludf.DUMMYFUNCTION("""COMPUTED_VALUE"""),60.0) -> 60 | B22: =IFERROR(__xludf.DUMMYFUNCTION("""COMPUTED_VALUE"""),900.037463159366) -> 900.03746 | C22: =IFERROR(__xludf.DUMMYFUNCTION("""COMPUTED_VALUE"""),0.0131161945681517) -> 0.013116195 | D22: =IFERROR(__xludf.DUMMYFUNCTION("""COMPUTED_VALUE"""),0.447691108366641) -> 0.44769111 | E22: =IFERROR(__xludf.DUMMYFUNCTION("""COMPUTED_VALUE"""),164.589350237165) -> 164.58935
A23: =IFERROR(__xludf.DUMMYFUNCTION("""COMPUTED_VALUE"""),66.0) -> 66 | B23: =IFERROR(__xludf.DUMMYFUNCTION("""COMPUTED_VALUE"""),2800.08862529524) -> 2800.0886 | C23: =IFERROR(__xludf.DUMMYFUNCTION("""COMPUTED_VALUE"""),0.0283447247543063) -> 0.028344725 | D23: =IFERROR(__xludf.DUMMYFUNCTION("""COMPUTED_VALUE"""),0.473124592218124) -> 0.47312459 | E23: =IFERROR(__xludf.DUMMYFUNCTION("""COMPUTED_VALUE"""),213.36385261829) -> 213.36385
A24: =IFERROR(__xludf.DUMMYFUNCTION("""COMPUTED_VALUE"""),68.0) -> 68 | B24: =IFERROR(__xludf.DUMMYFUNCTION("""COMPUTED_VALUE"""),2586.00557144932) -> 2586.0056 | C24: =IFERROR(__xludf.DUMMYFUNCTION("""COMPUTED_VALUE"""),0.0274897319044827) -> 0.027489732 | D24: =IFERROR(__xludf.DUMMYFUNCTION("""COMPUTED_VALUE"""),0.529659909168692) -> 0.52965991 | E24: =IFERROR(__xludf.DUMMYFUNCTION("""COMPUTED_VALUE"""),242.45960351137) -> 242.4596
A25: =IFERROR(__xludf.DUMMYFUNCTION("""COMPUTED_VALUE"""),72.0) -> 72 | B25: =IFERROR(__xludf.DUMMYFUNCTION("""COMPUTED_VALUE"""),2550.01434672332) -> 2550.0143 | C25: =IFERROR(__xludf.DUMMYFUNCTION("""COMPUTED_VALUE"""),0.0253428618114748) -> 0.025342862 | D25: =IFERROR(__xludf.DUMMYFUNCTION("""COMPUTED_VALUE"""),0.453059188138773) -> 0.45305919 | E25: =IFERROR(__xludf.DUMMYFUNCTION("""COMPUTED_VALUE"""),206.296501607547) -> 206.2965
A26: =IFERROR(__xludf.DUMMYFUNCTION("""COMPUTED_VALUE"""),74.0) -> 74 | B26: =IFERROR(__xludf.DUMMYFUNCTION("""COMPUTED_VALUE"""),1500.06911523446) -> 1500.0691 | C26: =IFERROR(__xludf.DUMMYFUNCTION("""COMPUTED_VALUE"""),0.0186272009394324) -> 0.018627201 | D26: =IFERROR(__xludf.DUMMYFUNCTION("""COMPUTED_VALUE"""),0.567193016128642) -> 0.56719302 | E26: =IFERROR(__xludf.DUMMYFUNCTION("""COMPUTED_VALUE"""),183.313587052481) -> 183.31359
A27: =IFERROR(__xludf.DUMMYFUNCTION("""COMPUTED_VALUE"""),78.0) -> 78 | B27: =IFERROR(__xludf.DUMMYFUNCTION("""COMPUTED_VALUE"""),1700.00514557557) -> 1700.0051 | C27: =IFERROR(__xludf.DUMMYFUNCTION("""COMPUTED_VALUE"""),0.0208441964872098) -> 0.020844196 | D27: =IFERROR(__xludf.DUMMYFUNCTION("""COMPUTED_VALUE"""),0.540432533338103) -> 0.54043253 | E27: =IFERROR(__xludf.DUMMYFUNCTION("""COMPUTED_VALUE"""),210.143377279933) -> 210.14338
A28: =IFERROR(__xludf.DUMMYFUNCTION("""COMPUTED_VALUE"""),82.0) -> 82 | B28: =IFERROR(__xludf.DUMMYFUNCTION("""COMPUTED_VALUE"""),3200.06689835853) -> 3200.0669 | C28: =IFERROR(__xludf.DUMMYFUNCTION("""COMPUTED_VALUE"""),0.0331521555375636) -> 0.033152156 | D28: =IFERROR(__xludf.DUMMYFUNCTION("""COMPUTED_VALUE"""),0.510928468995698) -> 0.51092847 | E28: =IFERROR(__xludf.DUMMYFUNCTION("""COMPUTED_VALUE"""),202.885044411915) -> 202.88504
A29: =IFERROR(__xludf.DUMMYFUNCTION("""COMPUTED_VALUE"""),86.0) -> 86 | B29: =IFERROR(__xludf.DUMMYFUNCTION("""COMPUTED_VALUE"""),1099.92960417535) -> 1099.9296 | C29: =IFERROR(__xludf.DUMMYFUNCTION("""COMPUTED_VALUE"""),0.015244711095523) -> 0.015244711 | D29: =IFERROR(__xludf.DUMMYFUNCTION("""COMPUTED_VALUE"""),0.480720316388739) -> 0.48072032 | E29: =IFERROR(__xludf.DUMMYFUNCTION("""COMPUTED_VALUE"""),147.278269645495) -> 147.27827
A30: =IFERROR(__xludf.DUMMYFUNCTION("""COMPUTED_VALUE"""),88.0) -> 88 | B30: =IFERROR(__xludf.DUMMYFUNCTION("""COMPUTED_VALUE"""),600.111531508275) -> 600.11153 | C30: =IFERROR(__xludf.DUMMYFUNCTION("""COMPUTED_VALUE"""),0.00844058512983285) -> 0.0084405851 | D30: =IFERROR(__xludf.DUMMYFUNCTION("""COMPUTED_VALUE"""),0.562988507898612) -> 0.56298851 | E30: =IFERROR(__xludf.DUMMYFUNCTION("""COMPUTED_VALUE"""),151.384953718919) -> 151.38495
A31: =IFERROR(__xludf.DUMMYFUNCTION("""COMPUTED_VALUE"""),90.0) -> 90 | B31: =IFERROR(__xludf.DUMMYFUNCTION("""COMPUTED_VALUE"""),950.038490144401) -> 950.03849 | C31: =IFERROR(__xludf.DUMMYFUNCTION("""COMPUTED_VALUE"""),0.0111592758991525) -> 0.011159276 | D31: =IFERROR(__xludf.DUMMYFUNCTION("""COMPUTED_VALUE"""),0.363760019771728) -> 0.36376002 | E31: =IFERROR(__xludf.DUMMYFUNCTION("""COMPUTED_VALUE"""),136.149717288547) -> 136.14972
A32: =IFERROR(__xludf.DUMMYFUNCTION("""COMPUTED_VALUE"""),92.0) -> 92 | B32: =IFERROR(__xludf.DUMMYFUNCTION("""COMPUTED_VALUE"""),2250.08164684126) -> 2250.0816 | C32: =IFERROR(__xludf.DUMMYFUNCTION("""COMPUTED_VALUE"""),0.0244770793122863) -> 0.024477079 | D32: =IFERROR(__xludf.DUMMYFUNCTION("""COMPUTED_VALUE"""),0.601973639790325) -> 0.60197364 | E32: =IFERROR(__xludf.DUMMYFUNCTION("""COMPUTED_VALUE"""),239.364125042426) -> 239.36413
A33: =IFERROR(__xludf.DUMMYFUNCTION("""COMPUTED_VALUE"""),94.0) -> 94 | B33: =IFERROR(__xludf.DUMMYFUNCTION("""COMPUTED_VALUE"""),3549.82638301964) -> 3549.8264 | C33: =IFERROR(__xludf.DUMMYFUNCTION("""COMPUTED_VALUE"""),0.0337051192337009) -> 0.033705119 | D33: =IFERROR(__xludf.DUMMYFUNCTION("""COMPUTED_VALUE"""),0.49257508816172) -> 0.49257509 | E33: =IFERROR(__xludf.DUMMYFUNCTION("""COMPUTED_VALUE"""),207.561832311018) -> 207.56183
A34: =IFERROR(__xludf.DUMMYFUNCTION("""COMPUTED_VALUE"""),96.0) -> 96 | B34: =IFERROR(__xludf.DUMMYFUNCTION("""COMPUTED_VALUE"""),1750.10153529075) -> 1750.1015 | C34: =IFERROR(__xludf.DUMMYFUNCTION("""COMPUTED_VALUE"""),0.0206283691294145) -> 0.020628369 | D34: =IFERROR(__xludf.DUMMYFUNCTION("""COMPUTED_VALUE"""),0.394082645387445) -> 0.39408265 | E34: =IFERROR(__xludf.DUMMYFUNCTION("""COMPUTED_VALUE"""),166.215610411859) -> 166.21561
A35: =IFERROR(__xludf.DUMMYFUNCTION("""COMPUTED_VALUE"""),98.0) -> 98 | B35: =IFERROR(__xludf.DUMMYFUNCTION("""COMPUTED_VALUE"""),1100.05917581326) -> 1100.0592 | C35: =IFERROR(__xludf.DUMMYFUNCTION("""COMPUTED_VALUE"""),0.0135866106593475) -> 0.013586611 | D35: =IFERROR(__xludf.DUMMYFUNCTION("""COMPUTED_VALUE"""),0.471028709603571) -> 0.47102871 | E35: =IFERROR(__xludf.DUMMYFUNCTION("""COMPUTED_VALUE"""),175.861622042772) -> 175.86162
A36: =IFERROR(__xludf.DUMMYFUNCTION("""COMPUTED_VALUE"""),100.0) -> 100 | B36: =IFERROR(__xludf.DUMMYFUNCTION("""COMPUTED_VALUE"""),1798.96340477767) -> 1798.9634 | C36: =IFERROR(__xludf.DUMMYFUNCTION("""COMPUTED_VALUE"""),0.021064185664472) -> 0.021064186 | D36: =IFERROR(__xludf.DUMMYFUNCTION("""COMPUTED_VALUE"""),0.47403199964435) -> 0.474032 | E36: =IFERROR(__xludf.DUMMYFUNCTION("""COMPUTED_VALUE"""),187.791335769321) -> 187.79134
A43: run | B43: rate | C43: cpu | D43: memoria_gb | E43: heap_mb
A44: =IFERROR(__xludf.DUMMYFUNCTION("FILTER(Tradicional[[run]:[heap_mb]], Tradicional[Outliers]=""OK"") "),3.0) -> 3 | B44: =IFERROR(__xludf.DUMMYFUNCTION("""COMPUTED_VALUE"""),2700.10810732223) -> 2700.1081 | C44: =IFERROR(__xludf.DUMMYFUNCTION("""COMPUTED_VALUE"""),0.0478483710874781) -> 0.047848371 | D44: =IFERROR(__xludf.DUMMYFUNCTION("""COMPUTED_VALUE"""),0.586409563862568) -> 0.58640956 | E44: =IFERROR(__xludf.DUMMYFUNCTION("""COMPUTED_VALUE"""),272.498703907557) -> 272.4987
A45: =IFERROR(__xludf.DUMMYFUNCTION("""COMPUTED_VALUE"""),7.0) -> 7 | B45: =IFERROR(__xludf.DUMMYFUNCTION("""COMPUTED_VALUE"""),1750.08781993183) -> 1750.0878 | C45: =IFERROR(__xludf.DUMMYFUNCTION("""COMPUTED_VALUE"""),0.0356302257635406) -> 0.035630226 | D45: =IFERROR(__xludf.DUMMYFUNCTION("""COMPUTED_VALUE"""),0.452527603645465) -> 0.4525276 | E45: =IFERROR(__xludf.DUMMYFUNCTION("""COMPUTED_VALUE"""),187.082972075808) -> 187.08297
A46: =IFERROR(__xludf.DUMMYFUNCTION("""COMPUTED_VALUE"""),9.0) -> 9 | B46: =IFERROR(__xludf.DUMMYFUNCTION("""COMPUTED_VALUE"""),1800.06806659516) -> 1800.0681 | C46: =IFERROR(__xludf.DUMMYFUNCTION("""COMPUTED_VALUE"""),0.0409843800038135) -> 0.04098438 | D46: =IFERROR(__xludf.DUMMYFUNCTION("""COMPUTED_VALUE"""),0.433634167617147) -> 0.43363417 | E46: =IFERROR(__xludf.DUMMYFUNCTION("""COMPUTED_VALUE"""),168.080363078289) -> 168.08036
...

Sheet Amostra
A1: Metricas | B1: Virtual | C1: Tradicional | E1: Metricas | F1: Virtual | G1: Tradicional
A2: Tamanho da Amostra | B2: =ROWS(Virtual_sem_outliers[run]) -> 39 | C2: =ROWS(Tradicional_sem_outilers[run]) -> 43 | E2: Tamanho da Amostra | F2: =ROWS(Virtual_sem_outliers[run]) -> 39 | G2: =ROWS(Tradicional_sem_outilers[run]) -> 43
A3: Valor critico | B3: =_xlfn.NORM.S.INV(1 - 0.05/2) -> 1.959964 | C3: =_xlfn.NORM.S.INV(1 - 0.05/2) -> 1.959964 | E3: Valor critico | F3: =_xlfn.NORM.S.INV(1 - 0.05/2) -> 1.959964 | G3: =_xlfn.NORM.S.INV(1 - 0.05/2) -> 1.959964
A4: Desvio padrão | B4: =Estatisticas_gerais!C21 -> 828.41522 | C4: =Estatisticas_gerais!C26 -> 940.78418 | E4: Desvio padrão | F4: =Estatisticas_gerais!D21 -> 0.0073270726 | G4: =Estatisticas_gerais!D26 -> 0.015388559
A5: Margem de Erro | B5: =0.1*Estatisticas_gerais!C17 -> 207.21398 | C5: =0.1*Estatisticas_gerais!C22 -> 200.81551 | E5: Margem de Erro | F5: =0.1*Estatisticas_gerais!D17 -> 0.0022569189 | G5: =0.1*Estatisticas_gerais!D22 -> 0.0039506364
A6: Resultado | B6: =((B3*B4)/B5)^2 -> 61.397997 | C6: =((C3*C4)/C5)^2 -> 84.310501 | E6: Resultado | F6: =((F3*F4)/F5)^2 -> 40.487902 | G6: =((G3*G4)/G5)^2 -> 58.285157
A9: Metricas | B9: Virtual | C9: Tradicional | E9: Metricas | F9: Virtual | G9: Tradicional
A10: Tamanho da Amostra | B10: =ROWS(Virtual_sem_outliers[run]) -> 39 | C10: =ROWS(Tradicional_sem_outilers[run]) -> 43 | E10: Tamanho da Amostra | F10: =ROWS(Virtual_sem_outliers[run]) -> 39 | G10: =ROWS(Tradicional_sem_outilers[run]) -> 43
A11: Valor critico | B11: =_xlfn.NORM.S.INV(1 - 0.05/2) -> 1.959964 | C11: =_xlfn.NORM.S.INV(1 - 0.05/2) -> 1.959964 | E11: Valor critico | F11: =_xlfn.NORM.S.INV(1 - 0.05/2) -> 1.959964 | G11: =_xlfn.NORM.S.INV(1 - 0.05/2) -> 1.959964
A12: Desvio padrão | B12: =Estatisticas_gerais!E21 -> 0.072375129 | C12: =Estatisticas_gerais!E26 -> 0.095080654 | E12: Desvio padrão | F12: =Estatisticas_gerais!F21 -> 43.3233 | G12: =Estatisticas_gerais!F26 -> 56.360231
A13: Margem de Erro | B13: =0.1*Estatisticas_gerais!E17 -> 0.04784022 | C13: =0.1*Estatisticas_gerais!E22 -> 0.047907712 | E13: Margem de Erro | F13: =0.1*Estatisticas_gerais!F17 -> 18.896076 | G13: =0.1*Estatisticas_gerais!F22 -> 19.534379
A14: Resultado | B14: =((B11*B12)/B13)^2 -> 8.7920175 | C14: =((C11*C12)/C13)^2 -> 15.13107 | E14: Resultado | F14: =((F11*F12)/F13)^2 -> 20.192773 | G14: =((G11*G12)/G13)^2 -> 31.977352

Sheet Margem_Erro
A1: Execuções | B1: Margem de Erro Estimada | C1: Tempo Total (h) | D1: Tempo Total (dias) | E1: Margem Atual - Esperada | G1: Executado | H1: Tempo
A2: 50 | B2: =(_xlfn.T.INV.2T(0.05, A2) *Estatisticas_gerais!C11)/SQRT(A2) -> 318.45536 | C2: =((H6+((Estatisticas_gerais!C7/50)*H7)*(A2/2))+(H6+((Estatisticas_gerais!C2/50)*H7)*(A2/2)))/24 -> 6.0721394 | D2: =C2 -> 6.0721394 | G2: Warmup | H2: 0.041666667
A3: =60 -> 60 | B3: =(_xlfn.T.INV.2T(0.05, A3) *Estatisticas_gerais!C11)/SQRT(A3) -> 289.51295 | C3: =((H6+((Estatisticas_gerais!C7/50)*H7)*(A3/2))+(H6+((Estatisticas_gerais!C2/50)*H7)*(A3/2)))/24 -> 7.2814747 | D3: =C3 -> 7.2814747 | E3: =$B$2-B3 -> 28.942417 | G3: runWarmup | H3: 0.16666667
A4: =A3+20 -> 80 | B4: =(_xlfn.T.INV.2T(0.05, A4) *Estatisticas_gerais!C11)/SQRT(A4) -> 249.44275 | C4: =((H6+((Estatisticas_gerais!C7/50)*H7)*(A4/2))+(H6+((Estatisticas_gerais!C2/50)*H7)*(A4/2)))/24 -> 9.7001453 | D4: =C4 -> 9.7001453 | E4: =$B$2-B4 -> 69.012619 | G4: cg | H4: 0.055555556
A5: =A4+20 -> 100 | B5: =(_xlfn.T.INV.2T(0.05, A5) *Estatisticas_gerais!C11)/SQRT(A5) -> 222.4254 | C5: =((H6+((Estatisticas_gerais!C7/50)*H7)*(A5/2))+(H6+((Estatisticas_gerais!C2/50)*H7)*(A5/2)))/24 -> 12.118816 | D5: =C5 -> 12.118816 | E5: =$B$2-B5 -> 96.029961 | G5: Pausa | H5: 0.041666667
G6: Fixos | H6: =SUM(H2:H5) -> 0.30555556
G7: loop | H7: 0.0625
A8: Execuções | B8: Margem de Erro Estimada | C8: Tempo Total (h) | D8: Tempo Total (dias) | E8: Margem Atual - Esperada
A9: 50 | B9: =(_xlfn.T.INV.2T(0.05, A9) *Estatisticas_gerais!C6)/SQRT(A9) -> 312.74618 | C9: =((H6+((Estatisticas_gerais!C7/50)*H7)*(A2/2))+(H6+((Estatisticas_gerais!C2/50)*H7)*(A2/2)))/24 -> 6.0721394 | D9: =C9 -> 6.0721394
A10: =60 -> 60 | B10: =(_xlfn.T.INV.2T(0.05, A10) *Estatisticas_gerais!C6)/SQRT(A10) -> 284.32264 | C10: =((H6+((Estatisticas_gerais!C7/50)*H7)*(A3/2))+(H6+((Estatisticas_gerais!C2/50)*H7)*(A3/2)))/24 -> 7.2814747 | D10: =C10 -> 7.2814747 | E10: =$B$9-B10 -> 28.423545
A11: =A10+20 -> 80 | B11: =(_xlfn.T.INV.2T(0.05, A11) *Estatisticas_gerais!C6)/SQRT(A11) -> 244.9708 | C11: =((H6+((Estatisticas_gerais!C7/50)*H7)*(A4/2))+(H6+((Estatisticas_gerais!C2/50)*H7)*(A4/2)))/24 -> 9.7001453 | D11: =C11 -> 9.7001453 | E11: =$B$9-B11 -> 67.77538
A12: =A11+20 -> 100 | B12: =(_xlfn.T.INV.2T(0.05, A12) *Estatisticas_gerais!C6)/SQRT(A12) -> 218.43782 | C12: =((H6+((Estatisticas_gerais!C7/50)*H7)*(A5/2))+(H6+((Estatisticas_gerais!C2/50)*H7)*(A5/2)))/24 -> 12.118816 | D12: =C12 -> 12.118816 | E12: =$B$9-B12 -> 94.308362

Sheet Estatisticas_gerais
A1: EndPoint | B1: Métrica | C1: rate | D1: cpu | E1: memoria_gb | F1: heap_mb
A2: Virtual | B2: Média | C2: =AVERAGE(Virtual[rate]) -> 2404.0344 | D2: =AVERAGE(Virtual[cpu]) -> 0.025143021 | E2: =AVERAGE(Virtual[memoria_gb]) -> 0.50094063 | F2: =AVERAGE(Virtual[heap_mb]) -> 200.04108
A3: Virtual | B3: Mediana | C3: =MEDIAN(Virtual[rate]) -> 2375.0998 | D3: =MEDIAN(Virtual[cpu]) -> 0.02523862 | E3: =MEDIAN(Virtual[memoria_gb]) -> 0.50963946 | F3: =MEDIAN(Virtual[heap_mb]) -> 206.92917
A4: Virtual | B4: Mínimo | C4: =MIN(Virtual[rate]) -> 600.08639 | D4: =MIN(Virtual[cpu]) -> 0.0029810589 | E4: =MIN(Virtual[memoria_gb]) -> 0.21541946 | F4: =MIN(Virtual[heap_mb]) -> 41.686623
A5: Virtual | B5: Máximo | C5: =MAX(Virtual[rate]) -> 4849.6982 | D5: =MAX(Virtual[cpu]) -> 0.044616423 | E5: =MAX(Virtual[memoria_gb]) -> 0.82700507 | F5: =MAX(Virtual[heap_mb]) -> 298.66084
A6: Virtual | B6: Desvio Padrão | C6: =STDEV(Virtual[rate]) -> 1101.0129 | D6: =STDEV(Virtual[cpu]) -> 0.0096459337 | E6: =STDEV(Virtual[memoria_gb]) -> 0.11432367 | F6: =STDEV(Virtual[heap_mb]) -> 57.010144
A7: Tradicional | B7: Média | C7: =AVERAGE(Tradicional[rate]) -> 2239.8131 | D7: =AVERAGE(Tradicional[cpu]) -> 0.042461743 | E7: =AVERAGE(Tradicional[memoria_gb]) -> 0.50196817 | F7: =AVERAGE(Tradicional[heap_mb]) -> 206.10973
A8: Tradicional | B8: Mediana | C8: =MEDIAN(Tradicional[rate]) -> 2075.0762 | D8: =MEDIAN(Tradicional[cpu]) -> 0.042593885 | E8: =MEDIAN(Tradicional[memoria_gb]) -> 0.48629695 | F8: =MEDIAN(Tradicional[heap_mb]) -> 199.49897
A9: Tradicional | B9: Mínimo | C9: =MIN(Tradicional[rate]) -> 400.12518 | D9: =MIN(Tradicional[cpu]) -> 0.00019308805 | E9: =MIN(Tradicional[memoria_gb]) -> 0.30733174 | F9: =MIN(Tradicional[heap_mb]) -> 91.550059
A10: Tradicional | B10: Máximo | C10: =MAX(Tradicional[rate]) -> 5149.5443 | D10: =MAX(Tradicional[cpu]) -> 0.073027541 | E10: =MAX(Tradicional[memoria_gb]) -> 0.87519042 | F10: =MAX(Tradicional[heap_mb]) -> 412.51688
A11: Tradicional | B11: Desvio Padrão | C11: =STDEV(Tradicional[rate]) -> 1121.1119 | D11: =STDEV(Tradicional[cpu]) -> 0.01678253 | E11: =STDEV(Tradicional[memoria_gb]) -> 0.12367137 | F11: =STDEV(Tradicional[heap_mb]) -> 65.396523
A16: EndPoint | B16: Métrica | C16: rate | D16: cpu | E16: memoria_gb | F16: heap_mb
A17: Virtual | B17: Média | C17: =AVERAGE(Virtual_sem_outliers[rate]) -> 2072.1398 | D17: =AVERAGE(Virtual_sem_outliers[cpu]) -> 0.022569189 | E17: =AVERAGE(Virtual_sem_outliers[memoria_gb]) -> 0.4784022 | F17: =AVERAGE(Virtual_sem_outliers[heap_mb]) -> 188.96076
A18: Virtual | B18: Mediana | C18: =MEDIAN(Virtual_sem_outliers[rate]) -> 2200.269 | D18: =MEDIAN(Virtual_sem_outliers[cpu]) -> 0.024434743 | E18: =MEDIAN(Virtual_sem_outliers[memoria_gb]) -> 0.49257509 | F18: =MEDIAN(Virtual_sem_outliers[heap_mb]) -> 192.05126
A19: Virtual | B19: Mínimo | C19: =MIN(Virtual_sem_outliers[rate]) -> 600.08639 | D19: =MIN(Virtual_sem_outliers[cpu]) -> 0.0084405851 | E19: =MIN(Virtual_sem_outliers[memoria_gb]) -> 0.30990809 | F19: =MIN(Virtual_sem_outliers[heap_mb]) -> 88.434899
A20: Virtual | B20: Máximo | C20: =MAX(Virtual_sem_outliers[rate]) -> 3549.8264 | D20: =MAX(Virtual_sem_outliers[cpu]) -> 0.035709497 | E20: =MAX(Virtual_sem_outliers[memoria_gb]) -> 0.60197364 | F20: =MAX(Virtual_sem_outliers[heap_mb]) -> 265.49738
A21: Virtual | B21: Desvio Padrão | C21: =STDEV(Virtual_sem_outliers[rate]) -> 828.41522 | D21: =STDEV(Virtual_sem_outliers[cpu]) -> 0.0073270726 | E21: =STDEV(Virtual_sem_outliers[memoria_gb]) -> 0.072375129 | F21: =STDEV(Virtual_sem_outliers[heap_mb]) -> 43.3233
A22: Tradicional | B22: Média | C22: =AVERAGE(Tradicional_sem_outilers[rate]) -> 2008.1551 | D22: =AVERAGE(Tradicional_sem_outilers[cpu]) -> 0.039506364 | E22: =AVERAGE(Tradicional_sem_outilers[memoria_gb]) -> 0.47907712 | F22: =AVERAGE(Tradicional_sem_outilers[heap_mb]) -> 195.34379
A23: Tradicional | B23: Mediana | C23: =MEDIAN(Tradicional_sem_outilers[rate]) -> 1870.6812 | D23: =MEDIAN(Tradicional_sem_outilers[cpu]) -> 0.040953333 | E23: =MEDIAN(Tradicional_sem_outilers[memoria_gb]) -> 0.48629695 | F23: =MEDIAN(Tradicional_sem_outilers[heap_mb]) -> 196.71631
A24: Tradicional | B24: Mínimo | C24: =MIN(Tradicional_sem_outilers[rate]) -> 400.12518 | D24: =MIN(Tradicional_sem_outilers[cpu]) -> 0.00019308805 | E24: =MIN(Tradicional_sem_outilers[memoria_gb]) -> 0.30733174 | F24: =MIN(Tradicional_sem_outilers[heap_mb]) -> 91.550059
A25: Tradicional | B25: Máximo | C25: =MAX(Tradicional_sem_outilers[rate]) -> 3900.0738 | D25: =MAX(Tradicional_sem_outilers[cpu]) -> 0.063400856 | E25: =MAX(Tradicional_sem_outilers[memoria_gb]) -> 0.63231288 | F25: =MAX(Tradicional_sem_outilers[heap_mb]) -> 285.48636
A26: Tradicional | B26: Desvio Padrão | C26: =STDEV(Tradicional_sem_outilers[rate]) -> 940.78418 | D26: =STDEV(Tradicional_sem_outilers[cpu]) -> 0.015388559 | E26: =STDEV(Tradicional_sem_outilers[memoria_gb]) -> 0.095080654 | F26: =STDEV(Tradicional_sem_outilers[heap_mb]) -> 56.360231

Sheet Intervalo_De_Confianca
A1: EndPoint | B1: Métrica | C1: rate | D1: cpu_mean | E1: mem_used_mb | F1: heap_used_mb
A2: Virtual | B2: Execuções | C2: =ROWS(Virtual_sem_outliers[run]) -> 39 | D2: =ROWS(Virtual_sem_outliers[run]) -> 39 | E2: =ROWS(Virtual_sem_outliers[run]) -> 39 | F2: =ROWS(Virtual_sem_outliers[run]) -> 39
A3: Virtual | B3: Graus de liberdade | C3: =ROWS(Virtual_sem_outliers[run])-1 -> 38 | D3: =ROWS(Virtual_sem_outliers[run])-1 -> 38 | E3: =ROWS(Virtual_sem_outliers[run])-1 -> 38 | F3: =ROWS(Virtual_sem_outliers[run])-1 -> 38
A4: Virtual | B4: Valor crítico t | C4: =_xlfn.T.INV(0.975, C3) -> 2.0243942 | D4: =_xlfn.T.INV(0.975, D3) -> 2.0243942 | E4: =_xlfn.T.INV(0.975, E3) -> 2.0243942 | F4: =_xlfn.T.INV(0.975, F3) -> 2.0243942
A5: Virtual | B5: Erro padrão da média | C5: =Estatisticas_gerais!C21/SQRT(C2) -> 132.6526 | D5: =Estatisticas_gerais!D21/SQRT(D2) -> 0.0011732706 | E5: =Estatisticas_gerais!E21/SQRT(E2) -> 0.011589296 | F5: =Estatisticas_gerais!F21/SQRT(F2) -> 6.93728
A6: Virtual | B6: Margem de erro | C6: =C4*C5 -> 268.54115 | D6: =D4*D5 -> 0.0023751622 | E6: =E4*E5 -> 0.023461303 | F6: =F4*F5 -> 14.043789
A7: Virtual | B7: IC_inferior | C7: =Estatisticas_gerais!C17-C6 -> 1803.5987 | D7: =Estatisticas_gerais!D17-D6 -> 0.020194027 | E7: =Estatisticas_gerais!E17-E6 -> 0.4549409 | F7: =Estatisticas_gerais!F17-F6 -> 174.91697
A8: Virtual | B8: IC_superior | C8: =Estatisticas_gerais!C17+C6 -> 2340.681 | D8: =Estatisticas_gerais!D17+D6 -> 0.024944351 | E8: =Estatisticas_gerais!E17+E6 -> 0.50186351 | F8: =Estatisticas_gerais!F17+F6 -> 203.00455
A11: EndPoint | B11: Métrica | C11: rate | D11: cpu_mean | E11: mem_used_mb | F11: heap_used_mb
A12: Tradicional | B12: Execuções | C12: =ROWS(Tradicional_sem_outilers[run]) -> 43 | D12: =ROWS(Tradicional_sem_outilers[run]) -> 43 | E12: =ROWS(Tradicional_sem_outilers[run]) -> 43 | F12: =ROWS(Tradicional_sem_outilers[run]) -> 43
A13: Tradicional | B13: Graus de liberdade | C13: =ROWS(Tradicional_sem_outilers[run])-1 -> 42 | D13: =ROWS(Tradicional_sem_outilers[run])-1 -> 42 | E13: =ROWS(Tradicional_sem_outilers[run])-1 -> 42 | F13: =ROWS(Tradicional_sem_outilers[run])-1 -> 42
A14: Tradicional | B14: Valor crítico t | C14: =_xlfn.T.INV(0.975, C13) -> 2.0180817 | D14: =_xlfn.T.INV(0.975, D13) -> 2.0180817 | E14: =_xlfn.T.INV(0.975, E13) -> 2.0180817 | F14: =_xlfn.T.INV(0.975, F13) -> 2.0180817
A15: Tradicional | B15: Erro padrão da média | C15: =Estatisticas_gerais!C26/SQRT(C12) -> 143.46824 | D15: =Estatisticas_gerais!D26/SQRT(D12) -> 0.0023467332 | E15: =Estatisticas_gerais!E26/SQRT(E12) -> 0.014499664 | F15: =Estatisticas_gerais!F26/SQRT(F12) -> 8.5948547
A16: Tradicional | B16: Margem de erro | C16: =C14*C15 -> 289.53064 | D16: =D14*D15 -> 0.0047358994 | E16: =E14*E15 -> 0.029261506 | F16: =F14*F15 -> 17.345119
A17: Tradicional | B17: IC_inferior | C17: =Estatisticas_gerais!C22-C16 -> 1718.6245 | D17: =Estatisticas_gerais!D22-D16 -> 0.034770464 | E17: =Estatisticas_gerais!E22-E16 -> 0.44981561 | F17: =Estatisticas_gerais!F22-F16 -> 177.99867
A18: Tradicional | B18: IC_superior | C18: =Estatisticas_gerais!C22+C16 -> 2297.6858 | D18: =Estatisticas_gerais!D22+D16 -> 0.044242263 | E18: =Estatisticas_gerais!E22+E16 -> 0.50833863 | F18: =Estatisticas_gerais!F22+F16 -> 212.68891
A22: EndPoint | B22: Metrica | C22: rate | D22: cpu_mean | E22: mem_used_mb | F22: heap
A23: Tradicional | B23: largura | C23: =(C18-C17)/Estatisticas_gerais!C22 -> 0.28835485 | D23: =(D18-D17)/Estatisticas_gerais!D22 -> 0.23975375 | E23: =(E18-E17)/Estatisticas_gerais!E22 -> 0.12215781 | F23: =(F18-F17)/Estatisticas_gerais!F22 -> 0.17758557
A24: Virtual | B24: largura | C24: =(C8-C7)/Estatisticas_gerais!C17 -> 0.25919211 | D24: =(D8-D7)/Estatisticas_gerais!D17 -> 0.21047829 | E24: =(E8-E7)/Estatisticas_gerais!E17 -> 0.098081918 | F24: =(F8-F7)/Estatisticas_gerais!F17 -> 0.14864238
