Workbook
Name virtual_limite_heap: Outliers!$F$14
Name virtual_limite_memoria: Outliers!$B$14
Name tradicional_limite_memoria: Outliers!$C$14
Name tradicional_limite_heap: Outliers!$G$14
Name tradicional_limite_lat_mean_s: Outliers!$C$6
Name virtual_limite_superior_cpu: Outliers!$F$6
Name tradicional_limite_inferior_cpu: Outliers!$G$5
Name tradicional_limite_superior_cpu: Outliers!$G$6
Name virtual_limite_lat_mean_s: Outliers!$B$6
Name virtual_limite_inferior_cpu: Outliers!$F$5

Sheet Dados
A1: run | B1: lat_mean_s | C1: lat_p50_s | D1: lat_p90_s | E1: lat_p95_s | F1: lat_p99_s | G1: lat_max_s | H1: requests | I1: rate | J1: throughput | K1: success | L1: bytes_in_total | M1: cpu_mean | N1: mem_used_mb | O1: heap_used_mb | P1: Outlier
A2: 2 | B2: 0.14391995 | C2: 0.10859756 | D2: 0.12519016 | E2: 0.20815853 | F2: 1.0466426 | G2: 9.8327429 | H2: 600000 | I2: 1000.0016 | J2: 999.82012 | K2: 0.99999667 | L2: 19799934 | M2: 0.036996808 | N2: 733.64169 | O2: 351.82679 | P2: =IF(OR(B2>virtual_limite_lat_mean_s, M2>virtual_limite_superior_cpu, M2<virtual_limite_inferior_cpu, N2 > virtual_limite_memoria, O2 > virtual_limite_heap ), "OUTLIER", "OK") -> OK
A3: 4 | B3: 0.12449752 | C3: 0.10880552 | D3: 0.12380736 | E3: 0.14138553 | F3: 0.37395508 | G3: 6.10279 | H3: 600000 | I3: 1000.0015 | J3: 999.77935 | K3: 1 | L3: 19800000 | M3: 0.035498498 | N3: 445.09838 | O3: 144.84547 | P3: =IF(OR(B3>virtual_limite_lat_mean_s, M3>virtual_limite_superior_cpu, M3<virtual_limite_inferior_cpu, N3 > virtual_limite_memoria, O3 > virtual_limite_heap ), "OUTLIER", "OK") -> OK
A4: 6 | B4: 0.11267483 | C4: 0.10840493 | D4: 0.11818753 | E4: 0.12789271 | F4: 0.21299431 | G4: 0.56202258 | H4: 600000 | I4: 1000.0009 | J4: 999.82195 | K4: 1 | L4: 19800000 | M4: 0.037002633 | N4: 507.43396 | O4: 232.92969 | P4: =IF(OR(B4>virtual_limite_lat_mean_s, M4>virtual_limite_superior_cpu, M4<virtual_limite_inferior_cpu, N4 > virtual_limite_memoria, O4 > virtual_limite_heap ), "OUTLIER", "OK") -> OK
A5: 8 | B5: 0.21155557 | C5: 0.11135917 | D5: 0.18273403 | E5: 0.56780583 | F5: 2.5841628 | G5: 13.390708 | H5: 600000 | I5: 1000.0016 | J5: 999.78187 | K5: 0.99997833 | L5: 19799571 | M5: 0.037071811 | N5: 403.45209 | O5: 90.933532 | P5: =IF(OR(B5>virtual_limite_lat_mean_s, M5>virtual_limite_superior_cpu, M5<virtual_limite_inferior_cpu, N5 > virtual_limite_memoria, O5 > virtual_limite_heap ), "OUTLIER", "OK") -> OK
A6: 10 | B6: 0.11399295 | C6: 0.10937035 | D6: 0.12148112 | E6: 0.13103565 | F6: 0.18657201 | G6: 1.6703134 | H6: 600000 | I6: 1000.0017 | J6: 999.8251 | K6: 1 | L6: 19800000 | M6: 0.038376457 | N6: 246.50758 | O6: 55.815836 | P6: =IF(OR(B6>virtual_limite_lat_mean_s, M6>virtual_limite_superior_cpu, M6<virtual_limite_inferior_cpu, N6 > virtual_limite_memoria, O6 > virtual_limite_heap ), "OUTLIER", "OK") -> OK
A7: 12 | B7: 0.11114546 | C7: 0.10882773 | D7: 0.11801974 | E7: 0.123314 | F7: 0.14522502 | G7: 0.36678129 | H7: 600000 | I7: 1000.0012 | J7: 999.81968 | K7: 1 | L7: 19800000 | M7: 0.039023056 | N7: 240.04122 | O7: 55.528643 | P7: =IF(OR(B7>virtual_limite_lat_mean_s, M7>virtual_limite_superior_cpu, M7<virtual_limite_inferior_cpu, N7 > virtual_limite_memoria, O7 > virtual_limite_heap ), "OUTLIER", "OK") -> OK
A8: 14 | B8: 0.11407766 | C8: 0.1095297 | D8: 0.1240008 | E8: 0.13681905 | F8: 0.1936668 | G8: 0.38096334 | H8: 600000 | I8: 1000.0016 | J8: 999.77026 | K8: 1 | L8: 19800000 | M8: 0.037286109 | N8: 276.95189 | O8: 73.003115 | P8: =IF(OR(B8>virtual_limite_lat_mean_s, M8>virtual_limite_superior_cpu, M8<virtual_limite_inferior_cpu, N8 > virtual_limite_memoria, O8 > virtual_limite_heap ), "OUTLIER", "OK") -> OK
A9: 16 | B9: 0.14643452 | C9: 0.11261624 | D9: 0.16256014 | E9: 0.22594911 | F9: 1.0200332 | G9: 8.6105164 | H9: 600000 | I9: 1000.0002 | J9: 999.82078 | K9: 1 | L9: 19800000 | M9: 0.036004483 | N9: 449.01711 | O9: 130.87939 | P9: =IF(OR(B9>virtual_limite_lat_mean_s, M9>virtual_limite_superior_cpu, M9<virtual_limite_inferior_cpu, N9 > virtual_limite_memoria, O9 > virtual_limite_heap ), "OUTLIER", "OK") -> OK
A10: 18 | B10: 11.849196 | C10: 1.099458 | D10: 36.748327 | E10: 49.380496 | F10: 72.535525 | G10: 112.45278 | H10: 600000 | I10: 1000.0014 | J10: 843.28957 | K10: 0.84344 | L10: 16700112 | M10: 0.03968898 | N10: 890.278 | O10: 422.15541 | P10: =IF(OR(B10>virtual_limite_lat_mean_s, M10>virtual_limite_superior_cpu, M10<virtual_limite_inferior_cpu, N10 > virtual_limite_memoria, O10 > virtual_limite_heap ), "OUTLIER", "OK") -> OUTLIER
A11: 20 | B11: 0.12354646 | C11: 0.10938333 | D11: 0.12401202 | E11: 0.14678939 | F11: 0.5146429 | G11: 4.8281994 | H11: 600000 | I11: 1000.0018 | J11: 994.51043 | K11: 1 | L11: 19800000 | M11: 0.037407857 | N11: 290.6296 | O11: 87.356559 | P11: =IF(OR(B11>virtual_limite_lat_mean_s, M11>virtual_limite_superior_cpu, M11<virtual_limite_inferior_cpu, N11 > virtual_limite_memoria, O11 > virtual_limite_heap ), "OUTLIER", "OK") -> OK
A12: 22 | B12: 0.1120736 | C12: 0.10898102 | D12: 0.11922203 | E12: 0.12697182 | F12: 0.16584159 | G12: 0.4433816 | H12: 600000 | I12: 1000.0011 | J12: 999.82217 | K12: 1 | L12: 19800000 | M12: 0.038177745 | N12: 254.80037 | O12: 61.275061 | P12: =IF(OR(B12>virtual_limite_lat_mean_s, M12>virtual_limite_superior_cpu, M12<virtual_limite_inferior_cpu, N12 > virtual_limite_memoria, O12 > virtual_limite_heap ), "OUTLIER", "OK") -> OK
A13: 24 | B13: 23.762475 | C13: 18.303255 | D13: 58.84183 | E13: 71.666991 | F13: 90.598769 | G13: 144.35169 | H13: 600000 | I13: 999.26832 | J13: 665.63371 | K13: 0.70268667 | L13: 13913196 | M13: 0.039070194 | N13: 775.35261 | O13: 400.45239 | P13: =IF(OR(B13>virtual_limite_lat_mean_s, M13>virtual_limite_superior_cpu, M13<virtual_limite_inferior_cpu, N13 > virtual_limite_memoria, O13 > virtual_limite_heap ), "OUTLIER", "OK") -> OUTLIER
... A51: 100 | B51: 24.260382 | C51: 1.1349255 | D51: 81.671293 | E51: 90.900346 | F51: 122.41965 | G51: 192.25726 | H51: 600000 | I51: 999.99987 | J51: 755.48651 | K51: 0.755685 | L51: 14962563 | M51: 0.038830993 | N51: 615.48045 | O51: 153.85275 | P51: =IF(OR(B51>virtual_limite_lat_mean_s, M51>virtual_limite_superior_cpu, M51<virtual_limite_inferior_cpu, N51 > virtual_limite_memoria, O51 > virtual_limite_heap ), "OUTLIER", "OK") -> OUTLIER
A54: run | B54: lat_mean_s | C54: lat_p50_s | D54: lat_p90_s | E54: lat_p95_s | F54: lat_p99_s | G54: lat_max_s | H54: requests | I54: rate | J54: throughput | K54: success | L54: bytes_in_total | M54: cpu_mean | N54: mem_used_mb | O54: heap_used_mb | P54: outlier
A55: 1 | B55: 0.2498236 | C55: 0.11106918 | D55: 0.1722662 | E55: 0.62791551 | F55: 3.9862205 | G55: 19.527779 | H55: 600000 | I55: 1000.0016 | J55: 999.6635 | K55: 0.99984167 | L55: 22196485 | M55: 0.08017136 | N55: 887.78157 | O55: 403.29796 | P55: =IF(OR(B55 > tradicional_limite_lat_mean_s,M55 > tradicional_limite_superior_cpu, M55 < tradicional_limite_inferior_cpu,N55 > tradicional_limite_memoria,O55 > tradicional_limite_heap ) , "OUTLIER", "OK") -> OUTLIER
A56: 3 | B56: 0.51600279 | C56: 0.11118923 | D56: 0.15158764 | E56: 1.0321371 | F56: 13.519594 | G56: 60.691363 | H56: 599999 | I56: 1000.0001 | J56: 946.82311 | K56: 0.99597333 | L56: 22110571 | M56: 0.077866849 | N56: 471.38069 | O56: 178.42502 | P56: =IF(OR(B56 > tradicional_limite_lat_mean_s,M56 > tradicional_limite_superior_cpu, M56 < tradicional_limite_inferior_cpu,N56 > tradicional_limite_memoria,O56 > tradicional_limite_heap ) , "OUTLIER", "OK") -> OUTLIER
A57: 5 | B57: 0.22098259 | C57: 0.11251912 | D57: 0.19469758 | E57: 0.49388015 | F57: 2.9712245 | G57: 13.632439 | H57: 600000 | I57: 1000.0016 | J57: 999.76057 | K57: 0.99994167 | L57: 22198705 | M57: 0.081831299 | N57: 668.99372 | O57: 311.77878 | P57: =IF(OR(B57 > tradicional_limite_lat_mean_s,M57 > tradicional_limite_superior_cpu, M57 < tradicional_limite_inferior_cpu,N57 > tradicional_limite_memoria,O57 > tradicional_limite_heap ) , "OUTLIER", "OK") -> OK
A58: 7 | B58: 0.11183385 | C58: 0.10972103 | D58: 0.11751604 | E58: 0.12332209 | F58: 0.14653583 | G58: 0.47722427 | H58: 600000 | I58: 1000 | J58: 999.81005 | K58: 1 | L58: 22200000 | M58: 0.084657753 | N58: 248.56912 | O58: 53.510956 | P58: =IF(OR(B58 > tradicional_limite_lat_mean_s,M58 > tradicional_limite_superior_cpu, M58 < tradicional_limite_inferior_cpu,N58 > tradicional_limite_memoria,O58 > tradicional_limite_heap ) , "OUTLIER", "OK") -> OUTLIER
A59: 9 | B59: 0.11532155 | C59: 0.11095518 | D59: 0.12620481 | E59: 0.13968434 | F59: 0.18532991 | G59: 0.36155184 | H59: 600000 | I59: 1000.0016 | J59: 999.67763 | K59: 1 | L59: 22200000 | M59: 0.083914305 | N59: 260.1567 | O59: 60.228837 | P59: =IF(OR(B59 > tradicional_limite_lat_mean_s,M59 > tradicional_limite_superior_cpu, M59 < tradicional_limite_inferior_cpu,N59 > tradicional_limite_memoria,O59 > tradicional_limite_heap ) , "OUTLIER", "OK") -> OK
A60: 11 | B60: 0.11540478 | C60: 0.11051676 | D60: 0.1247914 | E60: 0.13827863 | F60: 0.20756287 | G60: 0.63124961 | H60: 600000 | I60: 1000.0013 | J60: 999.81908 | K60: 1 | L60: 22200000 | M60: 0.08337566 | N60: 305.0978 | O60: 90.48557 | P60: =IF(OR(B60 > tradicional_limite_lat_mean_s,M60 > tradicional_limite_superior_cpu, M60 < tradicional_limite_inferior_cpu,N60 > tradicional_limite_memoria,O60 > tradicional_limite_heap ) , "OUTLIER", "OK") -> OK
A61: 13 | B61: 0.36062573 | C61: 0.11220754 | D61: 0.14568463 | E61: 0.21600011 | F61: 9.5872249 | G61: 64.146432 | H61: 600000 | I61: 1000.0006 | J61: 998.33218 | K61: 0.99851167 | L61: 22166959 | M61: 0.082077119 | N61: 665.81759 | O61: 288.47616 | P61: =IF(OR(B61 > tradicional_limite_lat_mean_s,M61 > tradicional_limite_superior_cpu, M61 < tradicional_limite_inferior_cpu,N61 > tradicional_limite_memoria,O61 > tradicional_limite_heap ) , "OUTLIER", "OK") -> OK
A62: 15 | B62: 0.42278102 | C62: 0.11194808 | D62: 0.16425685 | E62: 1.2362801 | F62: 10.09544 | G62: 70.001201 | H62: 600000 | I62: 1000.0018 | J62: 998.24673 | K62: 0.99842667 | L62: 22165072 | M62: 0.082327272 | N62: 599.99859 | O62: 207.99462 | P62: =IF(OR(B62 > tradicional_limite_lat_mean_s,M62 > tradicional_limite_superior_cpu, M62 < tradicional_limite_inferior_cpu,N62 > tradicional_limite_memoria,O62 > tradicional_limite_heap ) , "OUTLIER", "OK") -> OK
A63: 17 | B63: 0.42516789 | C63: 0.11410037 | D63: 0.63694228 | E63: 1.8036868 | F63: 7.0280214 | G63: 26.168789 | H63: 600000 | I63: 1000.0016 | J63: 998.92475 | K63: 0.99910667 | L63: 22180168 | M63: 0.080935695 | N63: 763.28332 | O63: 365.87154 | P63: =IF(OR(B63 > tradicional_limite_lat_mean_s,M63 > tradicional_limite_superior_cpu, M63 < tradicional_limite_inferior_cpu,N63 > tradicional_limite_memoria,O63 > tradicional_limite_heap ) , "OUTLIER", "OK") -> OUTLIER
A64: 19 | B64: 0.33193516 | C64: 0.11091647 | D64: 0.15742237 | E64: 0.97781786 | F64: 7.0865479 | G64: 27.494504 | H64: 600000 | I64: 1000.0004 | J64: 998.71028 | K64: 0.99890667 | L64: 22175728 | M64: 0.083058829 | N64: 529.67285 | O64: 222.15249 | P64: =IF(OR(B64 > tradicional_limite_lat_mean_s,M64 > tradicional_limite_superior_cpu, M64 < tradicional_limite_inferior_cpu,N64 > tradicional_limite_memoria,O64 > tradicional_limite_heap ) , "OUTLIER", "OK") -> OK
A65: 21 | B65: 0.91602753 | C65: 0.11341305 | D65: 2.5509197 | E65: 5.7541836 | F65: 12.279975 | G65: 40.28206 | H65: 600000 | I65: 1000.0016 | J65: 975.34749 | K65: 0.99592833 | L65: 22109609 | M65: 0.079169793 | N65: 820.1371 | O65: 383.10828 | P65: =IF(OR(B65 > tradicional_limite_lat_mean_s,M65 > tradicional_limite_superior_cpu, M65 < tradicional_limite_inferior_cpu,N65 > tradicional_limite_memoria,O65 > tradicional_limite_heap ) , "OUTLIER", "OK") -> OUTLIER
A66: 23 | B66: 0.30663482 | C66: 0.11299595 | D66: 0.40880587 | E66: 1.1229001 | F66: 4.3394483 | G66: 21.637876 | H66: 600000 | I66: 1000.0012 | J66: 973.58493 | K66: 0.9998 | L66: 22195560 | M66: 0.080650725 | N66: 495.01736 | O66: 196.54764 | P66: =IF(OR(B66 > tradicional_limite_lat_mean_s,M66 > tradicional_limite_superior_cpu, M66 < tradicional_limite_inferior_cpu,N66 > tradicional_limite_memoria,O66 > tradicional_limite_heap ) , "OUTLIER", "OK") -> OK
... A104: 99 | B104: 0.12811629 | C104: 0.11200325 | D104: 0.13282871 | E104: 0.16545061 | F104: 0.50622838 | G104: 4.0572851 | H104: 600000 | I104: 1000.0012 | J104: 999.81616 | K104: 1 | L104: 22200000 | M104: 0.080084339 | N104: 459.00628 | O104: 176.95378 | P104: =IF(OR(B104 > tradicional_limite_lat_mean_s,M104 > tradicional_limite_superior_cpu, M104 < tradicional_limite_inferior_cpu,N104 > tradicional_limite_memoria,O104 > tradicional_limite_heap ) , "OUTLIER", "OK") -> OK

Sheet Amostra Mínima
A1: Metricas | B1: Virtual | C1: Tradicional | E1: Metricas | F1: Virtual | G1: Tradicional
A2: Tamanho da Amostra | B2: =ROWS(Virtual_Sem_Outliers[run]) -> 35 | C2: =ROWS(Tradicional_Sem_Outliers[run]) -> 33 | E2: Tamanho da Amostra | F2: =ROWS(Virtual_Sem_Outliers[run]) -> 35 | G2: =ROWS(Tradicional_Sem_Outliers[run]) -> 33
A3: Valor critico | B3: =_xlfn.NORM.S.INV(1 - 0.05/2) -> 1.959964 | C3: =_xlfn.NORM.S.INV(1 - 0.05/2) -> 1.959964 | E3: Valor critico | F3: =_xlfn.NORM.S.INV(1 - 0.05/2) -> 1.959964 | G3: =_xlfn.NORM.S.INV(1 - 0.05/2) -> 1.959964
A4: Desvio padrão | B4: =Estatisticas!C19 -> 0.050474549 | C4: =Estatisticas!C24 -> 0.087460095 | E4: Desvio padrão | F4: =Estatisticas!H19 -> 0.0010956161 | G4: =Estatisticas!H24 -> 0.00095497343
A5: Margem de Erro | B5: =0.1*Estatisticas!C15 -> 0.014383868 | C5: =0.1*Estatisticas!C20 -> 0.017620232 | E5: Margem de Erro | F5: =0.1*Estatisticas!H15 -> 0.0036991031 | G5: =0.1*Estatisticas!G20 -> 0.19431863
A6: Resultado | B6: =((B3*B4)/B5)^2 -> 47.303111 | C6: =((C3*C4)/C5)^2 -> 94.643939 | E6: Resultado | F6: =((F3*F4)/F5)^2 -> 0.33699243 | G6: =((G3*G4)/G5)^2 -> 9.2779042e-05
A9: Metricas | B9: Virtual | C9: Tradicional | E9: Metricas | F9: Virtual | G9: Tradicional
A10: Tamanho da Amostra | B10: =ROWS(Virtual_Sem_Outliers[run]) -> 35 | C10: =ROWS(Tradicional_Sem_Outliers[run]) -> 33 | E10: Tamanho da Amostra | F10: =ROWS(Virtual_Sem_Outliers[run]) -> 35 | G10: =ROWS(Tradicional_Sem_Outliers[run]) -> 33
A11: Valor critico | B11: =_xlfn.NORM.S.INV(1 - 0.05/2) -> 1.959964 | C11: =_xlfn.NORM.S.INV(1 - 0.05/2) -> 1.959964 | E11: Valor critico | F11: =_xlfn.NORM.S.INV(1 - 0.05/2) -> 1.959964 | G11: =_xlfn.NORM.S.INV(1 - 0.05/2) -> 1.959964
A12: Desvio padrão | B12: =Estatisticas!I19 -> 149.32596 | C12: =Estatisticas!I24 -> 124.53789 | E12: Desvio padrão | F12: =Estatisticas!J19 -> 86.772686 | G12: =Estatisticas!J24 -> 73.731626
A13: Margem de Erro | B13: =0.1*Estatisticas!I15 -> 41.072199 | C13: =0.1*Estatisticas!I20 -> 46.222396 | E13: Margem de Erro | F13: =0.1*Estatisticas!J15 -> 14.223554 | G13: =0.1*Estatisticas!J20 -> 17.963109
A14: Resultado | B14: =((B11*B12)/B13)^2 -> 50.777453 | C14: =((C11*C12)/C13)^2 -> 27.886515 | E14: Resultado | F14: =((F11*F12)/F13)^2 -> 142.97036 | G14: =((G11*G12)/G13)^2 -> 64.72034

Sheet Intervalo_Confianca
A1: EndPoint | B1: Métrica | C1: lat_mean_s | D1: lat_p50_s | E1: lat_p90_s | F1: lat_p95_s | G1: lat_p99_s | H1: cpu_mean | I1: mem_used_mb | J1: heap_used_mb
A2: Virtual | B2: Execuções | C2: =ROWS(Virtual_Sem_Outliers[lat_mean_s_virtual]) -> 35 | D2: =ROWS(Virtual_Sem_Outliers[lat_mean_s_virtual]) -> 35 | E2: =ROWS(Virtual_Sem_Outliers[lat_mean_s_virtual]) -> 35 | F2: =ROWS(Virtual_Sem_Outliers[lat_mean_s_virtual]) -> 35 | G2: =ROWS(Virtual_Sem_Outliers[lat_mean_s_virtual]) -> 35 | H2: =ROWS(Virtual_Sem_Outliers[lat_mean_s_virtual]) -> 35 | I2: =ROWS(Virtual_Sem_Outliers[lat_mean_s_virtual]) -> 35 | J2: =ROWS(Virtual_Sem_Outliers[lat_mean_s_virtual]) -> 35
A3: Virtual | B3: Graus de liberdade | C3: =ROWS(Virtual_Sem_Outliers[lat_mean_s_virtual])-1 -> 34 | D3: =ROWS(Virtual_Sem_Outliers[lat_mean_s_virtual])-1 -> 34 | E3: =ROWS(Virtual_Sem_Outliers[lat_mean_s_virtual])-1 -> 34 | F3: =ROWS(Virtual_Sem_Outliers[lat_mean_s_virtual])-1 -> 34 | G3: =ROWS(Virtual_Sem_Outliers[lat_mean_s_virtual])-1 -> 34 | H3: =ROWS(Virtual_Sem_Outliers[lat_mean_s_virtual])-1 -> 34 | I3: =ROWS(Virtual_Sem_Outliers[lat_mean_s_virtual])-1 -> 34 | J3: =ROWS(Virtual_Sem_Outliers[lat_mean_s_virtual])-1 -> 34
A4: Virtual | B4: Valor crítico t | C4: =_xlfn.T.INV(0.975, C3) -> 2.0322445 | D4: =_xlfn.T.INV(0.975, D3) -> 2.0322445 | E4: =_xlfn.T.INV(0.975, E3) -> 2.0322445 | F4: =_xlfn.T.INV(0.975, F3) -> 2.0322445 | G4: =_xlfn.T.INV(0.975, G3) -> 2.0322445 | H4: =_xlfn.T.INV(0.975, H3) -> 2.0322445 | I4: =_xlfn.T.INV(0.975, I3) -> 2.0322445 | J4: =_xlfn.T.INV(0.975, J3) -> 2.0322445
A5: Virtual | B5: Erro padrão da média | C5: =Estatisticas!C19/SQRT(C2) -> 0.008531756 | D5: =Estatisticas!D19/SQRT(D2) -> 0.00019450937 | E5: =Estatisticas!E19/SQRT(E2) -> 0.00824182 | F5: =Estatisticas!F19/SQRT(F2) -> 0.035077424 | G5: =Estatisticas!G19/SQRT(G2) -> 0.24362363 | H5: =Estatisticas!H19/SQRT(H2) -> 0.00018519292 | I5: =Estatisticas!I19/SQRT(I2) -> 25.240694 | J5: =Estatisticas!J19/SQRT(J2) -> 14.667261
A6: Virtual | B6: Margem de erro | C6: =C4*C5 -> 0.017338614 | D6: =D4*D5 -> 0.0003952906 | E6: =E4*E5 -> 0.016749393 | F6: =F4*F5 -> 0.071285903 | G6: =G4*G5 -> 0.49510278 | H6: =H4*H5 -> 0.0003763573 | I6: =I4*I5 -> 51.295262 | J6: =J4*J5 -> 29.807461
A7: Virtual | B7: IC_inferior | C7: =Estatisticas!C15-C6 -> 0.12650007 | D7: =Estatisticas!D15-D6 -> 0.10923489 | E7: =Estatisticas!E15-E6 -> 0.12301185 | F7: =Estatisticas!F15-F6 -> 0.14763362 | G7: =Estatisticas!G15-G6 -> 0.56485978 | H7: =Estatisticas!H15-H6 -> 0.036614673 | I7: =Estatisticas!I15-I6 -> 359.42672 | J7: =Estatisticas!J15-J6 -> 112.42808
A8: Virtual | B8: IC_superior | C8: =Estatisticas!C15+C6 -> 0.16117729 | D8: =Estatisticas!D15+D6 -> 0.11002547 | E8: =Estatisticas!E15+E6 -> 0.15651064 | F8: =Estatisticas!F15+F6 -> 0.29020543 | G8: =Estatisticas!G15+G6 -> 1.5550653 | H8: =Estatisticas!H15+H6 -> 0.037367388 | I8: =Estatisticas!I15+I6 -> 462.01725 | J8: =Estatisticas!J15+J6 -> 172.043
A12: EndPoint | B12: Métrica | C12: lat_mean_s | D12: lat_p50_s | E12: lat_p90_s | F12: lat_p95_s | G12: lat_p99_s | H12: cpu_mean | I12: mem_used_mb | J12: heap_used_mb
A13: Tradicional | B13: Execuções | C13: =ROWS(Tradicional_Sem_Outliers[lat_mean_s_tradicional]) -> 33 | D13: =ROWS(Tradicional_Sem_Outliers[lat_mean_s_tradicional]) -> 33 | E13: =ROWS(Tradicional_Sem_Outliers[lat_mean_s_tradicional]) -> 33 | F13: =ROWS(Tradicional_Sem_Outliers[lat_mean_s_tradicional]) -> 33 | G13: =ROWS(Tradicional_Sem_Outliers[lat_mean_s_tradicional]) -> 33 | H13: =ROWS(Tradicional_Sem_Outliers[lat_mean_s_tradicional]) -> 33 | I13: =ROWS(Tradicional_Sem_Outliers[lat_mean_s_tradicional]) -> 33 | J13: =ROWS(Tradicional_Sem_Outliers[lat_mean_s_tradicional]) -> 33
A14: Tradicional | B14: Graus de liberdade | C14: =ROWS(Tradicional_Sem_Outliers[lat_mean_s_tradicional])-1 -> 32 | D14: =ROWS(Tradicional_Sem_Outliers[lat_mean_s_tradicional])-1 -> 32 | E14: =ROWS(Tradicional_Sem_Outliers[lat_mean_s_tradicional])-1 -> 32 | F14: =ROWS(Tradicional_Sem_Outliers[lat_mean_s_tradicional])-1 -> 32 | G14: =ROWS(Tradicional_Sem_Outliers[lat_mean_s_tradicional])-1 -> 32 | H14: =ROWS(Tradicional_Sem_Outliers[lat_mean_s_tradicional])-1 -> 32 | I14: =ROWS(Tradicional_Sem_Outliers[lat_mean_s_tradicional])-1 -> 32 | J14: =ROWS(Tradicional_Sem_Outliers[lat_mean_s_tradicional])-1 -> 32
A15: Tradicional | B15: Valor crítico t | C15: =_xlfn.T.INV(0.975, C14) -> 2.0369333 | D15: =_xlfn.T.INV(0.975, D14) -> 2.0369333 | E15: =_xlfn.T.INV(0.975, E14) -> 2.0369333 | F15: =_xlfn.T.INV(0.975, F14) -> 2.0369333 | G15: =_xlfn.T.INV(0.975, G14) -> 2.0369333 | H15: =_xlfn.T.INV(0.975, H14) -> 2.0369333 | I15: =_xlfn.T.INV(0.975, I14) -> 2.0369333 | J15: =_xlfn.T.INV(0.975, J14) -> 2.0369333
A16: Tradicional | B16: Erro padrão da média | C16: =Estatisticas!C24/SQRT(C13) -> 0.015224848 | D16: =Estatisticas!D24/SQRT(D13) -> 0.00032986608 | E16: =Estatisticas!E24/SQRT(E13) -> 0.0093771364 | F16: =Estatisticas!F24/SQRT(F13) -> 0.055172561 | G16: =Estatisticas!G24/SQRT(G13) -> 0.4869332 | H16: =Estatisticas!H24/SQRT(H13) -> 0.00016623954 | I16: =Estatisticas!I24/SQRT(I13) -> 21.679263 | J16: =Estatisticas!J24/SQRT(J13) -> 12.835029
A17: Tradicional | B17: Margem de erro | C17: =C15*C16 -> 0.031012001 | D17: =D15*D16 -> 0.00067191523 | E17: =E15*E16 -> 0.019100602 | F17: =F15*F16 -> 0.11238283 | G17: =G15*G16 -> 0.99185048 | H17: =H15*H16 -> 0.00033861885 | I17: =I15*I16 -> 44.159214 | J17: =J15*J16 -> 26.144098
A18: Tradicional | B18: IC_inferior | C18: =Estatisticas!C20-C17 -> 0.14519032 | D18: =Estatisticas!D20-D17 -> 0.11120335 | E18: =Estatisticas!E20-E17 -> 0.13623125 | F18: =Estatisticas!F20-F17 -> 0.2222033 | G18: =Estatisticas!G20-G17 -> 0.95133581 | H18: =Estatisticas!H20-H17 -> 0.082223286 | I18: =Estatisticas!I20-I17 -> 418.06475 | J18: =Estatisticas!J20-J17 -> 153.48699
A19: Tradicional | B19: IC_superior | C19: =Estatisticas!C20+C17 -> 0.20721433 | D19: =Estatisticas!D20+D17 -> 0.11254718 | E19: =Estatisticas!E20+E17 -> 0.17443245 | F19: =Estatisticas!F20+F17 -> 0.44696896 | G19: =Estatisticas!G20+G17 -> 2.9350368 | H19: =Estatisticas!H20+H17 -> 0.082900523 | I19: =Estatisticas!I20+I17 -> 506.38318 | J19: =Estatisticas!J20+J17 -> 205.77519
A22: EndPoint | B22: Metrica | C22: lat_mean_s | D22: lat_p50_s | E22: lat_p90_s | F22: lat_p95_s | G22: lat_p99_s | H22: cpu_mean | I22: mem_used_mb | J22: heap_used_mb
A23: Tradicional | B23: Largura_95 | C23: =(C19-C18)/Estatisticas!C20 -> 0.35200445 | D23: =(D19-D18)/Estatisticas!D20 -> 0.012011864 | E23: =(E19-E18)/Estatisticas!E20 -> 0.24593284 | F23: =(F19-F18)/Estatisticas!F20 -> 0.67177219 | G23: =(G19-G18)/Estatisticas!G20 -> 1.0208496 | H23: =(H19-H18)/Estatisticas!H20 -> 0.0082027868 | I23: =(I19-I18)/Estatisticas!I20 -> 0.1910728 | J23: =(J19-J18)/Estatisticas!J20 -> 0.29108656
A24: Virtual | B24: Largura_95 | C24: =(C8-C7)/Estatisticas!C15 -> 0.24108417 | D24: =(D8-D7)/Estatisticas!D15 -> 0.0072113462 | E24: =(E8-E7)/Estatisticas!E15 -> 0.23968581 | F24: =(F8-F7)/Estatisticas!F15 -> 0.65125214 | G24: =(G8-G7)/Estatisticas!G15 -> 0.93418918 | H24: =(H8-H7)/Estatisticas!H15 -> 0.020348571 | I24: =(I8-I7)/Estatisticas!I15 -> 0.24978094 | J24: =(J8-J7)/Estatisticas!J15 -> 0.41912816

Sheet Outliers
A1: Métrica | B1: virtual | C1: tradicional | E1: Métrica | F1: virtual | G1: tradicional
A2: Q1 | B2: =QUARTILE(Virtual[lat_mean_s], 1) -> 0.11451144 | C2: =QUARTILE(Tradicional[lat_mean_s], 1) -> 0.11697403 | E2: Q1 | F2: =QUARTILE(Virtual[cpu_mean], 1) -> 0.036062944 | G2: =QUARTILE(Tradicional[cpu_mean], 1) -> 0.08115182
A3: Q3 | B3: =QUARTILE(Virtual[lat_mean_s], 3) -> 0.32647964 | C3: =QUARTILE(Tradicional[lat_mean_s], 3) -> 0.33707702 | E3: Q3 | F3: =QUARTILE(Virtual[cpu_mean], 3) -> 0.038270599 | G3: =QUARTILE(Tradicional[cpu_mean], 3) -> 0.083314394
A4: IQR | B4: =B3 - B2 -> 0.2119682 | C4: =C3 - C2 -> 0.22010299 | E4: IQR | F4: =F3 - F2 -> 0.0022076551 | G4: =G3 - G2 -> 0.0021625738
A5: Limite inferior | B5: =B2 - 1.5 * B4 -> -0.20344086 | C5: =C2 - 1.5 * C4 -> -0.21318046 | E5: Limite inferior | F5: =F2 - 1.5 * F4 -> 0.032751461 | G5: =G2 - 1.5 * G4 -> 0.077907959
A6: Limite superior | B6: =B2 + 1.5 * B4 -> 0.43246374 | C6: =C2 + 1.5 * C4 -> 0.44712852 | E6: Limite superior | F6: =F2 + 1.5 * F4 -> 0.039374427 | G6: =G2 + 1.5 * G4 -> 0.084395681
A9: Métrica | B9: virtual | C9: tradicional | E9: Métrica | F9: virtual | G9: tradicional
A10: Q1 | B10: =QUARTILE(Virtual[mem_used_mb], 1) -> 291.25332 | C10: =QUARTILE(Tradicional[mem_used_mb], 1) -> 338.14516 | E10: Q1 | F10: =QUARTILE(Virtual[heap_used_mb], 1) -> 88.250802 | G10: =QUARTILE(Tradicional[heap_used_mb], 1) -> 100.25188
A11: Q3 | B11: =QUARTILE(Virtual[mem_used_mb], 3) -> 624.86355 | C11: =QUARTILE(Tradicional[mem_used_mb], 3) -> 610.99306 | E11: Q3 | F11: =QUARTILE(Virtual[heap_used_mb], 3) -> 295.63547 | G11: =QUARTILE(Tradicional[heap_used_mb], 3) -> 281.27054
A12: IQR | B12: =B11 - B10 -> 333.61023 | C12: =C11 - C10 -> 272.8479 | E12: IQR | F12: =F11 - F10 -> 207.38467 | G12: =G11 - G10 -> 181.01866
A13: Limite inferior | B13: =B10 - 1.5 * B12 -> -209.16203 | C13: =C10 - 1.5 * C12 -> -71.126697 | E13: Limite inferior | F13: =F10 - 1.5 * F12 -> -222.8262 | G13: =G10 - 1.5 * G12 -> -171.2761
A14: Limite superior | B14: =B10 + 1.5 * B12 -> 791.66867 | C14: =C10 + 1.5 * C12 -> 747.41701 | E14: Limite superior | F14: =F10 + 1.5 * F12 -> 399.32781 | G14: =G10 + 1.5 * G12 -> 371.77987

Sheet Dados_sem_outliers
A1: run | B1: lat_mean_s_virtual | C1: lat_p50_s | D1: lat_p90_s | E1: lat_p95_s | F1: lat_p99_s | G1: lat_max_s | H1: requests | I1: rate | J1: throughput | K1: success | L1: bytes_in_total | M1: cpu_mean | N1: mem_used_mb | O1: heap_used_mb
A2: =IFERROR(__xludf.DUMMYFUNCTION("FILTER(Dados!A2:O51, Dados!P2:P51 = ""OK"") "),2.0) -> 2 | B2: =IFERROR(__xludf.DUMMYFUNCTION("""COMPUTED_VALUE"""),0.143919951) -> 0.14391995 | C2: =IFERROR(__xludf.DUMMYFUNCTION("""COMPUTED_VALUE"""),0.10859756) -> 0.10859756 | D2: =IFERROR(__xludf.DUMMYFUNCTION("""COMPUTED_VALUE"""),0.125190161) -> 0.12519016 | E2: =IFERROR(__xludf.DUMMYFUNCTION("""COMPUTED_VALUE"""),0.208158526) -> 0.20815853 | F2: =IFERROR(__xludf.DUMMYFUNCTION("""COMPUTED_VALUE"""),1.046642551) -> 1.0466426 | G2: =IFERROR(__xludf.DUMMYFUNCTION("""COMPUTED_VALUE"""),9.832742925) -> 9.8327429 | H2: =IFERROR(__xludf.DUMMYFUNCTION("""COMPUTED_VALUE"""),600000.0) -> 600000 | I2: =IFERROR(__xludf.DUMMYFUNCTION("""COMPUTED_VALUE"""),1000.00161084592) -> 1000.0016 | J2: =IFERROR(__xludf.DUMMYFUNCTION("""COMPUTED_VALUE"""),999.820119086586) -> 999.82012 | K2: =IFERROR(__xludf.DUMMYFUNCTION("""COMPUTED_VALUE"""),0.999996666666666) -> 0.99999667 | L2: =IFERROR(__xludf.DUMMYFUNCTION("""COMPUTED_VALUE"""),1.9799934E7) -> 19799934 | M2: =IFERROR(__xludf.DUMMYFUNCTION("""COMPUTED_VALUE"""),0.0369968075897993) -> 0.036996808 | N2: =IFERROR(__xludf.DUMMYFUNCTION("""COMPUTED_VALUE"""),733.641687760966) -> 733.64169 | O2: =IFERROR(__xludf.DUMMYFUNCTION("""COMPUTED_VALUE"""),351.826790106101) -> 351.82679
A3: =IFERROR(__xludf.DUMMYFUNCTION("""COMPUTED_VALUE"""),4.0) -> 4 | B3: =IFERROR(__xludf.DUMMYFUNCTION("""COMPUTED_VALUE"""),0.124497518) -> 0.12449752 | C3: =IFERROR(__xludf.DUMMYFUNCTION("""COMPUTED_VALUE"""),0.108805519) -> 0.10880552 | D3: =IFERROR(__xludf.DUMMYFUNCTION("""COMPUTED_VALUE"""),0.123807358) -> 0.12380736 | E3: =IFERROR(__xludf.DUMMYFUNCTION("""COMPUTED_VALUE"""),0.141385531) -> 0.14138553 | F3: =IFERROR(__xludf.DUMMYFUNCTION("""COMPUTED_VALUE"""),0.373955079) -> 0.37395508 | G3: =IFERROR(__xludf.DUMMYFUNCTION("""COMPUTED_VALUE"""),6.102789987) -> 6.10279 | H3: =IFERROR(__xludf.DUMMYFUNCTION("""COMPUTED_VALUE"""),600000.0) -> 600000 | I3: =IFERROR(__xludf.DUMMYFUNCTION("""COMPUTED_VALUE"""),1000.00146625881) -> 1000.0015 | J3: =IFERROR(__xludf.DUMMYFUNCTION("""COMPUTED_VALUE"""),999.779353145778) -> 999.77935 | K3: =IFERROR(__xludf.DUMMYFUNCTION("""COMPUTED_VALUE"""),1.0) -> 1 | L3: =IFERROR(__xludf.DUMMYFUNCTION("""COMPUTED_VALUE"""),1.98E7) -> 19800000 | M3: =IFERROR(__xludf.DUMMYFUNCTION("""COMPUTED_VALUE"""),0.0354984976479933) -> 0.035498498 | N3: =IFERROR(__xludf.DUMMYFUNCTION("""COMPUTED_VALUE"""),445.098380735203) -> 445.09838 | O3: =IFERROR(__xludf.DUMMYFUNCTION("""COMPUTED_VALUE"""),144.845465723673) -> 144.84547
A4: =IFERROR(__xludf.DUMMYFUNCTION("""COMPUTED_VALUE"""),6.0) -> 6 | B4: =IFERROR(__xludf.DUMMYFUNCTION("""COMPUTED_VALUE"""),0.112674829) -> 0.11267483 | C4: =IFERROR(__xludf.DUMMYFUNCTION("""COMPUTED_VALUE"""),0.108404927) -> 0.10840493 | D4: =IFERROR(__xludf.DUMMYFUNCTION("""COMPUTED_VALUE"""),0.118187534) -> 0.11818753 | E4: =IFERROR(__xludf.DUMMYFUNCTION("""COMPUTED_VALUE"""),0.127892709) -> 0.12789271 | F4: =IFERROR(__xludf.DUMMYFUNCTION("""COMPUTED_VALUE"""),0.212994313) -> 0.21299431 | G4: =IFERROR(__xludf.DUMMYFUNCTION("""COMPUTED_VALUE"""),0.56202258) -> 0.56202258 | H4: =IFERROR(__xludf.DUMMYFUNCTION("""COMPUTED_VALUE"""),600000.0) -> 600000 | I4: =IFERROR(__xludf.DUMMYFUNCTION("""COMPUTED_VALUE"""),1000.00091665084) -> 1000.0009 | J4: =IFERROR(__xludf.DUMMYFUNCTION("""COMPUTED_VALUE"""),999.821948073134) -> 999.82195 | K4: =IFERROR(__xludf.DUMMYFUNCTION("""COMPUTED_VALUE"""),1.0) -> 1 | L4: =IFERROR(__xludf.DUMMYFUNCTION("""COMPUTED_VALUE"""),1.98E7) -> 19800000 | M4: =IFERROR(__xludf.DUMMYFUNCTION("""COMPUTED_VALUE"""),0.0370026325852842) -> 0.037002633 | N4: =IFERROR(__xludf.DUMMYFUNCTION("""COMPUTED_VALUE"""),507.433959220606) -> 507.43396 | O4: =IFERROR(__xludf.DUMMYFUNCTION("""COMPUTED_VALUE"""),232.92969235834) -> 232.92969
A5: =IFERROR(__xludf.DUMMYFUNCTION("""COMPUTED_VALUE"""),8.0) -> 8 | B5: =IFERROR(__xludf.DUMMYFUNCTION("""COMPUTED_VALUE"""),0.211555571) -> 0.21155557 | C5: =IFERROR(__xludf.DUMMYFUNCTION("""COMPUTED_VALUE"""),0.111359169) -> 0.11135917 | D5: =IFERROR(__xludf.DUMMYFUNCTION("""COMPUTED_VALUE"""),0.182734035) -> 0.18273403 | E5: =IFERROR(__xludf.DUMMYFUNCTION("""COMPUTED_VALUE"""),0.567805831) -> 0.56780583 | F5: =IFERROR(__xludf.DUMMYFUNCTION("""COMPUTED_VALUE"""),2.584162808) -> 2.5841628 | G5: =IFERROR(__xludf.DUMMYFUNCTION("""COMPUTED_VALUE"""),13.390707582) -> 13.390708 | H5: =IFERROR(__xludf.DUMMYFUNCTION("""COMPUTED_VALUE"""),600000.0) -> 600000 | I5: =IFERROR(__xludf.DUMMYFUNCTION("""COMPUTED_VALUE"""),1000.00161889428) -> 1000.0016 | J5: =IFERROR(__xludf.DUMMYFUNCTION("""COMPUTED_VALUE"""),999.781865717339) -> 999.78187 | K5: =IFERROR(__xludf.DUMMYFUNCTION("""COMPUTED_VALUE"""),0.999978333333333) -> 0.99997833 | L5: =IFERROR(__xludf.DUMMYFUNCTION("""COMPUTED_VALUE"""),1.9799571E7) -> 19799571 | M5: =IFERROR(__xludf.DUMMYFUNCTION("""COMPUTED_VALUE"""),0.0370718111161936) -> 0.037071811 | N5: =IFERROR(__xludf.DUMMYFUNCTION("""COMPUTED_VALUE"""),403.452087583541) -> 403.45209 | O5: =IFERROR(__xludf.DUMMYFUNCTION("""COMPUTED_VALUE"""),90.933531637494) -> 90.933532
A6: =IFERROR(__xludf.DUMMYFUNCTION("""COMPUTED_VALUE"""),10.0) -> 10 | B6: =IFERROR(__xludf.DUMMYFUNCTION("""COMPUTED_VALUE"""),0.113992954) -> 0.11399295 | C6: =IFERROR(__xludf.DUMMYFUNCTION("""COMPUTED_VALUE"""),0.109370352) -> 0.10937035 | D6: =IFERROR(__xludf.DUMMYFUNCTION("""COMPUTED_VALUE"""),0.121481125) -> 0.12148112 | E6: =IFERROR(__xludf.DUMMYFUNCTION("""COMPUTED_VALUE"""),0.131035647) -> 0.13103565 | F6: =IFERROR(__xludf.DUMMYFUNCTION("""COMPUTED_VALUE"""),0.186572009) -> 0.18657201 | G6: =IFERROR(__xludf.DUMMYFUNCTION("""COMPUTED_VALUE"""),1.670313411) -> 1.6703134 | H6: =IFERROR(__xludf.DUMMYFUNCTION("""COMPUTED_VALUE"""),600000.0) -> 600000 | I6: =IFERROR(__xludf.DUMMYFUNCTION("""COMPUTED_VALUE"""),1000.0016750478) -> 1000.0017 | J6: =IFERROR(__xludf.DUMMYFUNCTION("""COMPUTED_VALUE"""),999.825100160305) -> 999.8251 | K6: =IFERROR(__xludf.DUMMYFUNCTION("""COMPUTED_VALUE"""),1.0) -> 1 | L6: =IFERROR(__xludf.DUMMYFUNCTION("""COMPUTED_VALUE"""),1.98E7) -> 19800000 | M6: =IFERROR(__xludf.DUMMYFUNCTION("""COMPUTED_VALUE"""),0.0383764570685618) -> 0.038376457 | N6: =IFERROR(__xludf.DUMMYFUNCTION("""COMPUTED_VALUE"""),246.507576945628) -> 246.50758 | O6: =IFERROR(__xludf.DUMMYFUNCTION("""COMPUTED_VALUE"""),55.8158362828768) -> 55.815836
A7: =IFERROR(__xludf.DUMMYFUNCTION("""COMPUTED_VALUE"""),12.0) -> 12 | B7: =IFERROR(__xludf.DUMMYFUNCTION("""COMPUTED_VALUE"""),0.111145463) -> 0.11114546 | C7: =IFERROR(__xludf.DUMMYFUNCTION("""COMPUTED_VALUE"""),0.108827734) -> 0.10882773 | D7: =IFERROR(__xludf.DUMMYFUNCTION("""COMPUTED_VALUE"""),0.118019745) -> 0.11801974 | E7: =IFERROR(__xludf.DUMMYFUNCTION("""COMPUTED_VALUE"""),0.123314002) -> 0.123314 | F7: =IFERROR(__xludf.DUMMYFUNCTION("""COMPUTED_VALUE"""),0.145225021) -> 0.14522502 | G7: =IFERROR(__xludf.DUMMYFUNCTION("""COMPUTED_VALUE"""),0.366781289) -> 0.36678129 | H7: =IFERROR(__xludf.DUMMYFUNCTION("""COMPUTED_VALUE"""),600000.0) -> 600000 | I7: =IFERROR(__xludf.DUMMYFUNCTION("""COMPUTED_VALUE"""),1000.00122838817) -> 1000.0012 | J7: =IFERROR(__xludf.DUMMYFUNCTION("""COMPUTED_VALUE"""),999.819681497293) -> 999.81968 | K7: =IFERROR(__xludf.DUMMYFUNCTION("""COMPUTED_VALUE"""),1.0) -> 1 | L7: =IFERROR(__xludf.DUMMYFUNCTION("""COMPUTED_VALUE"""),1.98E7) -> 19800000 | M7: =IFERROR(__xludf.DUMMYFUNCTION("""COMPUTED_VALUE"""),0.0390230563076923) -> 0.039023056 | N7: =IFERROR(__xludf.DUMMYFUNCTION("""COMPUTED_VALUE"""),240.041218235417) -> 240.04122 | O7: =IFERROR(__xludf.DUMMYFUNCTION("""COMPUTED_VALUE"""),55.5286426094921) -> 55.528643
A8: =IFERROR(__xludf.DUMMYFUNCTION("""COMPUTED_VALUE"""),14.0) -> 14 | B8: =IFERROR(__xludf.DUMMYFUNCTION("""COMPUTED_VALUE"""),0.114077662) -> 0.11407766 | C8: =IFERROR(__xludf.DUMMYFUNCTION("""COMPUTED_VALUE"""),0.109529698) -> 0.1095297 | D8: =IFERROR(__xludf.DUMMYFUNCTION("""COMPUTED_VALUE"""),0.124000801) -> 0.1240008 | E8: =IFERROR(__xludf.DUMMYFUNCTION("""COMPUTED_VALUE"""),0.136819047) -> 0.13681905 | F8: =IFERROR(__xludf.DUMMYFUNCTION("""COMPUTED_VALUE"""),0.1936668) -> 0.1936668 | G8: =IFERROR(__xludf.DUMMYFUNCTION("""COMPUTED_VALUE"""),0.380963344) -> 0.38096334 | H8: =IFERROR(__xludf.DUMMYFUNCTION("""COMPUTED_VALUE"""),600000.0) -> 600000 | I8: =IFERROR(__xludf.DUMMYFUNCTION("""COMPUTED_VALUE"""),1000.00161833261) -> 1000.0016 | J8: =IFERROR(__xludf.DUMMYFUNCTION("""COMPUTED_VALUE"""),999.7702648487) -> 999.77026 | K8: =IFERROR(__xludf.DUMMYFUNCTION("""COMPUTED_VALUE"""),1.0) -> 1 | L8: =IFERROR(__xludf.DUMMYFUNCTION("""COMPUTED_VALUE"""),1.98E7) -> 19800000 | M8: =IFERROR(__xludf.DUMMYFUNCTION("""COMPUTED_VALUE"""),0.0372861087274247) -> 0.037286109 | N8: =IFERROR(__xludf.DUMMYFUNCTION("""COMPUTED_VALUE"""),276.951887509659) -> 276.95189 | O8: =IFERROR(__xludf.DUMMYFUNCTION("""COMPUTED_VALUE"""),73.0031150464909) -> 73.003115
A9: =IFERROR(__xludf.DUMMYFUNCTION("""COMPUTED_VALUE"""),16.0) -> 16 | B9: =IFERROR(__xludf.DUMMYFUNCTION("""COMPUTED_VALUE"""),0.146434523) -> 0.14643452 | C9: =IFERROR(__xludf.DUMMYFUNCTION("""COMPUTED_VALUE"""),0.112616244) -> 0.11261624 | D9: =IFERROR(__xludf.DUMMYFUNCTION("""COMPUTED_VALUE"""),0.162560137) -> 0.16256014 | E9: =IFERROR(__xludf.DUMMYFUNCTION("""COMPUTED_VALUE"""),0.225949108) -> 0.22594911 | F9: =IFERROR(__xludf.DUMMYFUNCTION("""COMPUTED_VALUE"""),1.02003324) -> 1.0200332 | G9: =IFERROR(__xludf.DUMMYFUNCTION("""COMPUTED_VALUE"""),8.610516367) -> 8.6105164 | H9: =IFERROR(__xludf.DUMMYFUNCTION("""COMPUTED_VALUE"""),600000.0) -> 600000 | I9: =IFERROR(__xludf.DUMMYFUNCTION("""COMPUTED_VALUE"""),1000.00022426671) -> 1000.0002 | J9: =IFERROR(__xludf.DUMMYFUNCTION("""COMPUTED_VALUE"""),999.820775465525) -> 999.82078 | K9: =IFERROR(__xludf.DUMMYFUNCTION("""COMPUTED_VALUE"""),1.0) -> 1 | L9: =IFERROR(__xludf.DUMMYFUNCTION("""COMPUTED_VALUE"""),1.98E7) -> 19800000 | M9: =IFERROR(__xludf.DUMMYFUNCTION("""COMPUTED_VALUE"""),0.0360044827513377) -> 0.036004483 | N9: =IFERROR(__xludf.DUMMYFUNCTION("""COMPUTED_VALUE"""),449.017108288352) -> 449.01711 | O9: =IFERROR(__xludf.DUMMYFUNCTION("""COMPUTED_VALUE"""),130.879385371666) -> 130.87939
A10: =IFERROR(__xludf.DUMMYFUNCTION("""COMPUTED_VALUE"""),20.0) -> 20 | B10: =IFERROR(__xludf.DUMMYFUNCTION("""COMPUTED_VALUE"""),0.123546462) -> 0.12354646 | C10: =IFERROR(__xludf.DUMMYFUNCTION("""COMPUTED_VALUE"""),0.109383325) -> 0.10938333 | D10: =IFERROR(__xludf.DUMMYFUNCTION("""COMPUTED_VALUE"""),0.12401202) -> 0.12401202 | E10: =IFERROR(__xludf.DUMMYFUNCTION("""COMPUTED_VALUE"""),0.146789394) -> 0.14678939 | F10: =IFERROR(__xludf.DUMMYFUNCTION("""COMPUTED_VALUE"""),0.514642901) -> 0.5146429 | G10: =IFERROR(__xludf.DUMMYFUNCTION("""COMPUTED_VALUE"""),4.828199395) -> 4.8281994 | H10: =IFERROR(__xludf.DUMMYFUNCTION("""COMPUTED_VALUE"""),600000.0) -> 600000 | I10: =IFERROR(__xludf.DUMMYFUNCTION("""COMPUTED_VALUE"""),1000.00179089154) -> 1000.0018 | J10: =IFERROR(__xludf.DUMMYFUNCTION("""COMPUTED_VALUE"""),994.510428772465) -> 994.51043 | K10: =IFERROR(__xludf.DUMMYFUNCTION("""COMPUTED_VALUE"""),1.0) -> 1 | L10: =IFERROR(__xludf.DUMMYFUNCTION("""COMPUTED_VALUE"""),1.98E7) -> 19800000 | M10: =IFERROR(__xludf.DUMMYFUNCTION("""COMPUTED_VALUE"""),0.0374078567101329) -> 0.037407857 | N10: =IFERROR(__xludf.DUMMYFUNCTION("""COMPUTED_VALUE"""),290.629600491689) -> 290.6296 | O10: =IFERROR(__xludf.DUMMYFUNCTION("""COMPUTED_VALUE"""),87.3565588786189) -> 87.356559
A11: =IFERROR(__xludf.DUMMYFUNCTION("""COMPUTED_VALUE"""),22.0) -> 22 | B11: =IFERROR(__xludf.DUMMYFUNCTION("""COMPUTED_VALUE"""),0.112073597) -> 0.1120736 | C11: =IFERROR(__xludf.DUMMYFUNCTION("""COMPUTED_VALUE"""),0.108981025) -> 0.10898102 | D11: =IFERROR(__xludf.DUMMYFUNCTION("""COMPUTED_VALUE"""),0.11922203) -> 0.11922203 | E11: =IFERROR(__xludf.DUMMYFUNCTION("""COMPUTED_VALUE"""),0.126971818) -> 0.12697182 | F11: =IFERROR(__xludf.DUMMYFUNCTION("""COMPUTED_VALUE"""),0.165841593) -> 0.16584159 | G11: =IFERROR(__xludf.DUMMYFUNCTION("""COMPUTED_VALUE"""),0.443381598) -> 0.4433816 | H11: =IFERROR(__xludf.DUMMYFUNCTION("""COMPUTED_VALUE"""),600000.0) -> 600000 | I11: =IFERROR(__xludf.DUMMYFUNCTION("""COMPUTED_VALUE"""),1000.00112322126) -> 1000.0011 | J11: =IFERROR(__xludf.DUMMYFUNCTION("""COMPUTED_VALUE"""),999.822167428381) -> 999.82217 | K11: =IFERROR(__xludf.DUMMYFUNCTION("""COMPUTED_VALUE"""),1.0) -> 1 | L11: =IFERROR(__xludf.DUMMYFUNCTION("""COMPUTED_VALUE"""),1.98E7) -> 19800000 | M11: =IFERROR(__xludf.DUMMYFUNCTION("""COMPUTED_VALUE"""),0.0381777453695652) -> 0.038177745 | N11: =IFERROR(__xludf.DUMMYFUNCTION("""COMPUTED_VALUE"""),254.800371440702) -> 254.80037 | O11: =IFERROR(__xludf.DUMMYFUNCTION("""COMPUTED_VALUE"""),61.275060515164) -> 61.275061
A12: =IFERROR(__xludf.DUMMYFUNCTION("""COMPUTED_VALUE"""),30.0) -> 30 | B12: =IFERROR(__xludf.DUMMYFUNCTION("""COMPUTED_VALUE"""),0.111236712) -> 0.11123671 | C12: =IFERROR(__xludf.DUMMYFUNCTION("""COMPUTED_VALUE"""),0.108700888) -> 0.10870089 | D12: =IFERROR(__xludf.DUMMYFUNCTION("""COMPUTED_VALUE"""),0.119127164) -> 0.11912716 | E12: =IFERROR(__xludf.DUMMYFUNCTION("""COMPUTED_VALUE"""),0.125447282) -> 0.12544728 | F12: =IFERROR(__xludf.DUMMYFUNCTION("""COMPUTED_VALUE"""),0.146265758) -> 0.14626576 | G12: =IFERROR(__xludf.DUMMYFUNCTION("""COMPUTED_VALUE"""),0.299041131) -> 0.29904113 | H12: =IFERROR(__xludf.DUMMYFUNCTION("""COMPUTED_VALUE"""),600000.0) -> 600000 | I12: =IFERROR(__xludf.DUMMYFUNCTION("""COMPUTED_VALUE"""),1000.00098736264) -> 1000.001 | J12: =IFERROR(__xludf.DUMMYFUNCTION("""COMPUTED_VALUE"""),999.823392214152) -> 999.82339 | K12: =IFERROR(__xludf.DUMMYFUNCTION("""COMPUTED_VALUE"""),1.0) -> 1 | L12: =IFERROR(__xludf.DUMMYFUNCTION("""COMPUTED_VALUE"""),1.98E7) -> 19800000 | M12: =IFERROR(__xludf.DUMMYFUNCTION("""COMPUTED_VALUE"""),0.038623443673913) -> 0.038623444 | N12: =IFERROR(__xludf.DUMMYFUNCTION("""COMPUTED_VALUE"""),234.694717956504) -> 234.69472 | O12: =IFERROR(__xludf.DUMMYFUNCTION("""COMPUTED_VALUE"""),49.3406224348908) -> 49.340622
A13: =IFERROR(__xludf.DUMMYFUNCTION("""COMPUTED_VALUE"""),32.0) -> 32 | B13: =IFERROR(__xludf.DUMMYFUNCTION("""COMPUTED_VALUE"""),0.114524893) -> 0.11452489 | C13: =IFERROR(__xludf.DUMMYFUNCTION("""COMPUTED_VALUE"""),0.109972468) -> 0.10997247 | D13: =IFERROR(__xludf.DUMMYFUNCTION("""COMPUTED_VALUE"""),0.126907513) -> 0.12690751 | E13: =IFERROR(__xludf.DUMMYFUNCTION("""COMPUTED_VALUE"""),0.138853721) -> 0.13885372 | F13: =IFERROR(__xludf.DUMMYFUNCTION("""COMPUTED_VALUE"""),0.17944721) -> 0.17944721 | G13: =IFERROR(__xludf.DUMMYFUNCTION("""COMPUTED_VALUE"""),0.781143276) -> 0.78114328 | H13: =IFERROR(__xludf.DUMMYFUNCTION("""COMPUTED_VALUE"""),600000.0) -> 600000 | I13: =IFERROR(__xludf.DUMMYFUNCTION("""COMPUTED_VALUE"""),1000.00040113349) -> 1000.0004 | J13: =IFERROR(__xludf.DUMMYFUNCTION("""COMPUTED_VALUE"""),999.823074564815) -> 999.82307 | K13: =IFERROR(__xludf.DUMMYFUNCTION("""COMPUTED_VALUE"""),1.0) -> 1 | L13: =IFERROR(__xludf.DUMMYFUNCTION("""COMPUTED_VALUE"""),1.98E7) -> 19800000 | M13: =IFERROR(__xludf.DUMMYFUNCTION("""COMPUTED_VALUE"""),0.0379841860802676) -> 0.037984186 | N13: =IFERROR(__xludf.DUMMYFUNCTION("""COMPUTED_VALUE"""),235.175575902744) -> 235.17558 | O13: =IFERROR(__xludf.DUMMYFUNCTION("""COMPUTED_VALUE"""),49.2468930251306) -> 49.246893
A14: =IFERROR(__xludf.DUMMYFUNCTION("""COMPUTED_VALUE"""),34.0) -> 34 | B14: =IFERROR(__xludf.DUMMYFUNCTION("""COMPUTED_VALUE"""),0.111493342) -> 0.11149334 | C14: =IFERROR(__xludf.DUMMYFUNCTION("""COMPUTED_VALUE"""),0.108965187) -> 0.10896519 | D14: =IFERROR(__xludf.DUMMYFUNCTION("""COMPUTED_VALUE"""),0.11877828) -> 0.11877828 | E14: =IFERROR(__xludf.DUMMYFUNCTION("""COMPUTED_VALUE"""),0.12585047) -> 0.12585047 | F14: =IFERROR(__xludf.DUMMYFUNCTION("""COMPUTED_VALUE"""),0.150117235) -> 0.15011723 | G14: =IFERROR(__xludf.DUMMYFUNCTION("""COMPUTED_VALUE"""),0.362771636) -> 0.36277164 | H14: =IFERROR(__xludf.DUMMYFUNCTION("""COMPUTED_VALUE"""),600000.0) -> 600000 | I14: =IFERROR(__xludf.DUMMYFUNCTION("""COMPUTED_VALUE"""),1000.00180278491) -> 1000.0018 | J14: =IFERROR(__xludf.DUMMYFUNCTION("""COMPUTED_VALUE"""),999.822860545612) -> 999.82286 | K14: =IFERROR(__xludf.DUMMYFUNCTION("""COMPUTED_VALUE"""),1.0) -> 1 | L14: =IFERROR(__xludf.DUMMYFUNCTION("""COMPUTED_VALUE"""),1.98E7) -> 19800000 | M14: =IFERROR(__xludf.DUMMYFUNCTION("""COMPUTED_VALUE"""),0.0363090571956521) -> 0.036309057 | N14: =IFERROR(__xludf.DUMMYFUNCTION("""COMPUTED_VALUE"""),299.132266450604) -> 299.13227 | O14: =IFERROR(__xludf.DUMMYFUNCTION("""COMPUTED_VALUE"""),75.890818847469) -> 75.890819
A15: =IFERROR(__xludf.DUMMYFUNCTION("""COMPUTED_VALUE"""),36.0) -> 36 | B15: =IFERROR(__xludf.DUMMYFUNCTION("""COMPUTED_VALUE"""),0.114477893) -> 0.11447789 | C15: =IFERROR(__xludf.DUMMYFUNCTION("""COMPUTED_VALUE"""),0.108915376) -> 0.10891538 | D15: =IFERROR(__xludf.DUMMYFUNCTION("""COMPUTED_VALUE"""),0.124911276) -> 0.12491128 | E15: =IFERROR(__xludf.DUMMYFUNCTION("""COMPUTED_VALUE"""),0.138611221) -> 0.13861122 | F15: =IFERROR(__xludf.DUMMYFUNCTION("""COMPUTED_VALUE"""),0.209316707) -> 0.20931671 | G15: =IFERROR(__xludf.DUMMYFUNCTION("""COMPUTED_VALUE"""),1.058011328) -> 1.0580113 | H15: =IFERROR(__xludf.DUMMYFUNCTION("""COMPUTED_VALUE"""),600000.0) -> 600000 | I15: =IFERROR(__xludf.DUMMYFUNCTION("""COMPUTED_VALUE"""),1000.00171597794) -> 1000.0017 | J15: =IFERROR(__xludf.DUMMYFUNCTION("""COMPUTED_VALUE"""),999.741743362053) -> 999.74174 | K15: =IFERROR(__xludf.DUMMYFUNCTION("""COMPUTED_VALUE"""),1.0) -> 1 | L15: =IFERROR(__xludf.DUMMYFUNCTION("""COMPUTED_VALUE"""),1.98E7) -> 19800000 | M15: =IFERROR(__xludf.DUMMYFUNCTION("""COMPUTED_VALUE"""),0.0371225797416388) -> 0.03712258 | N15: =IFERROR(__xludf.DUMMYFUNCTION("""COMPUTED_VALUE"""),293.124482142109) -> 293.12448 | O15: =IFERROR(__xludf.DUMMYFUNCTION("""COMPUTED_VALUE"""),82.3301272374142) -> 82.330127
A16: =IFERROR(__xludf.DUMMYFUNCTION("""COMPUTED_VALUE"""),38.0) -> 38 | B16: =IFERROR(__xludf.DUMMYFUNCTION("""COMPUTED_VALUE"""),0.136752696) -> 0.1367527 | C16: =IFERROR(__xludf.DUMMYFUNCTION("""COMPUTED_VALUE"""),0.108709343) -> 0.10870934 | D16: =IFERROR(__xludf.DUMMYFUNCTION("""COMPUTED_VALUE"""),0.132643832) -> 0.13264383 | E16: =IFERROR(__xludf.DUMMYFUNCTION("""COMPUTED_VALUE"""),0.194612605) -> 0.1946126 | F16: =IFERROR(__xludf.DUMMYFUNCTION("""COMPUTED_VALUE"""),0.923557216) -> 0.92355722 | G16: =IFERROR(__xludf.DUMMYFUNCTION("""COMPUTED_VALUE"""),5.290283853) -> 5.2902839 | H16: =IFERROR(__xludf.DUMMYFUNCTION("""COMPUTED_VALUE"""),600000.0) -> 600000 | I16: =IFERROR(__xludf.DUMMYFUNCTION("""COMPUTED_VALUE"""),1000.00007364722) -> 1000.0001 | J16: =IFERROR(__xludf.DUMMYFUNCTION("""COMPUTED_VALUE"""),999.8134123881) -> 999.81341 | K16: =IFERROR(__xludf.DUMMYFUNCTION("""COMPUTED_VALUE"""),1.0) -> 1 | L16: =IFERROR(__xludf.DUMMYFUNCTION("""COMPUTED_VALUE"""),1.98E7) -> 19800000 | M16: =IFERROR(__xludf.DUMMYFUNCTION("""COMPUTED_VALUE"""),0.0373702564861203) -> 0.037370256 | N16: =IFERROR(__xludf.DUMMYFUNCTION("""COMPUTED_VALUE"""),436.961509822406) -> 436.96151 | O16: =IFERROR(__xludf.DUMMYFUNCTION("""COMPUTED_VALUE"""),150.853461181416) -> 150.85346
A17: =IFERROR(__xludf.DUMMYFUNCTION("""COMPUTED_VALUE"""),42.0) -> 42 | B17: =IFERROR(__xludf.DUMMYFUNCTION("""COMPUTED_VALUE"""),0.114506952) -> 0.11450695 | C17: =IFERROR(__xludf.DUMMYFUNCTION("""COMPUTED_VALUE"""),0.108732889) -> 0.10873289 | D17: =IFERROR(__xludf.DUMMYFUNCTION("""COMPUTED_VALUE"""),0.120808525) -> 0.12080852 | E17: =IFERROR(__xludf.DUMMYFUNCTION("""COMPUTED_VALUE"""),0.131787415) -> 0.13178741 | F17: =IFERROR(__xludf.DUMMYFUNCTION("""COMPUTED_VALUE"""),0.245612524) -> 0.24561252 | G17: =IFERROR(__xludf.DUMMYFUNCTION("""COMPUTED_VALUE"""),1.232186744) -> 1.2321867 | H17: =IFERROR(__xludf.DUMMYFUNCTION("""COMPUTED_VALUE"""),599999.0) -> 599999 | I17: =IFERROR(__xludf.DUMMYFUNCTION("""COMPUTED_VALUE"""),999.999952176589) -> 999.99995 | J17: =IFERROR(__xludf.DUMMYFUNCTION("""COMPUTED_VALUE"""),999.822599049293) -> 999.8226 | K17: =IFERROR(__xludf.DUMMYFUNCTION("""COMPUTED_VALUE"""),1.0) -> 1 | L17: =IFERROR(__xludf.DUMMYFUNCTION("""COMPUTED_VALUE"""),1.9799967E7) -> 19799967 | M17: =IFERROR(__xludf.DUMMYFUNCTION("""COMPUTED_VALUE"""),0.0370017680903009) -> 0.037001768 | N17: =IFERROR(__xludf.DUMMYFUNCTION("""COMPUTED_VALUE"""),399.068326189044) -> 399.06833 | O17: =IFERROR(__xludf.DUMMYFUNCTION("""COMPUTED_VALUE"""),98.1574241293352) -> 98.157424
A18: =IFERROR(__xludf.DUMMYFUNCTION("""COMPUTED_VALUE"""),44.0) -> 44 | B18: =IFERROR(__xludf.DUMMYFUNCTION("""COMPUTED_VALUE"""),0.160570866) -> 0.16057087 | C18: =IFERROR(__xludf.DUMMYFUNCTION("""COMPUTED_VALUE"""),0.109832302) -> 0.1098323 | D18: =IFERROR(__xludf.DUMMYFUNCTION("""COMPUTED_VALUE"""),0.145246118) -> 0.14524612 | E18: =IFERROR(__xludf.DUMMYFUNCTION("""COMPUTED_VALUE"""),0.212139713) -> 0.21213971 | F18: =IFERROR(__xludf.DUMMYFUNCTION("""COMPUTED_VALUE"""),1.682631179) -> 1.6826312 | G18: =IFERROR(__xludf.DUMMYFUNCTION("""COMPUTED_VALUE"""),13.729631515) -> 13.729632 | H18: =IFERROR(__xludf.DUMMYFUNCTION("""COMPUTED_VALUE"""),600000.0) -> 600000 | I18: =IFERROR(__xludf.DUMMYFUNCTION("""COMPUTED_VALUE"""),1000.00102055937) -> 1000.001 | J18: =IFERROR(__xludf.DUMMYFUNCTION("""COMPUTED_VALUE"""),999.763919825197) -> 999.76392 | K18: =IFERROR(__xludf.DUMMYFUNCTION("""COMPUTED_VALUE"""),0.999986666666666) -> 0.99998667 | L18: =IFERROR(__xludf.DUMMYFUNCTION("""COMPUTED_VALUE"""),1.9799736E7) -> 19799736 | M18: =IFERROR(__xludf.DUMMYFUNCTION("""COMPUTED_VALUE"""),0.0361342676516722) -> 0.036134268 | N18: =IFERROR(__xludf.DUMMYFUNCTION("""COMPUTED_VALUE"""),597.641455456092) -> 597.64146 | O18: =IFERROR(__xludf.DUMMYFUNCTION("""COMPUTED_VALUE"""),300.365315193353) -> 300.36532
A19: =IFERROR(__xludf.DUMMYFUNCTION("""COMPUTED_VALUE"""),46.0) -> 46 | B19: =IFERROR(__xludf.DUMMYFUNCTION("""COMPUTED_VALUE"""),0.116445897) -> 0.1164459 | C19: =IFERROR(__xludf.DUMMYFUNCTION("""COMPUTED_VALUE"""),0.110527042) -> 0.11052704 | D19: =IFERROR(__xludf.DUMMYFUNCTION("""COMPUTED_VALUE"""),0.129837725) -> 0.12983772 | E19: =IFERROR(__xludf.DUMMYFUNCTION("""COMPUTED_VALUE"""),0.144913037) -> 0.14491304 | F19: =IFERROR(__xludf.DUMMYFUNCTION("""COMPUTED_VALUE"""),0.20894931) -> 0.20894931 | G19: =IFERROR(__xludf.DUMMYFUNCTION("""COMPUTED_VALUE"""),1.254154763) -> 1.2541548 | H19: =IFERROR(__xludf.DUMMYFUNCTION("""COMPUTED_VALUE"""),600000.0) -> 600000 | I19: =IFERROR(__xludf.DUMMYFUNCTION("""COMPUTED_VALUE"""),1000.00178249151) -> 1000.0018 | J19: =IFERROR(__xludf.DUMMYFUNCTION("""COMPUTED_VALUE"""),999.781237150989) -> 999.78124 | K19: =IFERROR(__xludf.DUMMYFUNCTION("""COMPUTED_VALUE"""),1.0) -> 1 | L19: =IFERROR(__xludf.DUMMYFUNCTION("""COMPUTED_VALUE"""),1.98E7) -> 19800000 | M19: =IFERROR(__xludf.DUMMYFUNCTION("""COMPUTED_VALUE"""),0.0355613182257525) -> 0.035561318 | N19: =IFERROR(__xludf.DUMMYFUNCTION("""COMPUTED_VALUE"""),325.274064204131) -> 325.27406 | O19: =IFERROR(__xludf.DUMMYFUNCTION("""COMPUTED_VALUE"""),93.7516225256571) -> 93.751623
A20: =IFERROR(__xludf.DUMMYFUNCTION("""COMPUTED_VALUE"""),48.0) -> 48 | B20: =IFERROR(__xludf.DUMMYFUNCTION("""COMPUTED_VALUE"""),0.112795295) -> 0.1127953 | C20: =IFERROR(__xludf.DUMMYFUNCTION("""COMPUTED_VALUE"""),0.109258783) -> 0.10925878 | D20: =IFERROR(__xludf.DUMMYFUNCTION("""COMPUTED_VALUE"""),0.121071798) -> 0.1210718 | E20: =IFERROR(__xludf.DUMMYFUNCTION("""COMPUTED_VALUE"""),0.130742079) -> 0.13074208 | F20: =IFERROR(__xludf.DUMMYFUNCTION("""COMPUTED_VALUE"""),0.171443283) -> 0.17144328 | G20: =IFERROR(__xludf.DUMMYFUNCTION("""COMPUTED_VALUE"""),0.357163254) -> 0.35716325 | H20: =IFERROR(__xludf.DUMMYFUNCTION("""COMPUTED_VALUE"""),600000.0) -> 600000 | I20: =IFERROR(__xludf.DUMMYFUNCTION("""COMPUTED_VALUE"""),1000.00113235294) -> 1000.0011 | J20: =IFERROR(__xludf.DUMMYFUNCTION("""COMPUTED_VALUE"""),999.82030002955) -> 999.8203 | K20: =IFERROR(__xludf.DUMMYFUNCTION("""COMPUTED_VALUE"""),1.0) -> 1 | L20: =IFERROR(__xludf.DUMMYFUNCTION("""COMPUTED_VALUE"""),1.98E7) -> 19800000 | M20: =IFERROR(__xludf.DUMMYFUNCTION("""COMPUTED_VALUE"""),0.0354808312876254) -> 0.035480831 | N20: =IFERROR(__xludf.DUMMYFUNCTION("""COMPUTED_VALUE"""),689.454184167572) -> 689.45418 | O20: =IFERROR(__xludf.DUMMYFUNCTION("""COMPUTED_VALUE"""),278.745295091108) -> 278.7453
A21: =IFERROR(__xludf.DUMMYFUNCTION("""COMPUTED_VALUE"""),50.0) -> 50 | B21: =IFERROR(__xludf.DUMMYFUNCTION("""COMPUTED_VALUE"""),0.20140883) -> 0.20140883 | C21: =IFERROR(__xludf.DUMMYFUNCTION("""COMPUTED_VALUE"""),0.111203945) -> 0.11120394 | D21: =IFERROR(__xludf.DUMMYFUNCTION("""COMPUTED_VALUE"""),0.161611376) -> 0.16161138 | E21: =IFERROR(__xludf.DUMMYFUNCTION("""COMPUTED_VALUE"""),0.378609068) -> 0.37860907 | F21: =IFERROR(__xludf.DUMMYFUNCTION("""COMPUTED_VALUE"""),2.514814476) -> 2.5148145 | G21: =IFERROR(__xludf.DUMMYFUNCTION("""COMPUTED_VALUE"""),40.148690464) -> 40.14869 | H21: =IFERROR(__xludf.DUMMYFUNCTION("""COMPUTED_VALUE"""),600000.0) -> 600000 | I21: =IFERROR(__xludf.DUMMYFUNCTION("""COMPUTED_VALUE"""),1000.00044500853) -> 1000.0004 | J21: =IFERROR(__xludf.DUMMYFUNCTION("""COMPUTED_VALUE"""),999.790294434411) -> 999.79029 | K21: =IFERROR(__xludf.DUMMYFUNCTION("""COMPUTED_VALUE"""),0.999971666666666) -> 0.99997167 | L21: =IFERROR(__xludf.DUMMYFUNCTION("""COMPUTED_VALUE"""),1.9799439E7) -> 19799439 | M21: =IFERROR(__xludf.DUMMYFUNCTION("""COMPUTED_VALUE"""),0.0357941074021739) -> 0.035794107 | N21: =IFERROR(__xludf.DUMMYFUNCTION("""COMPUTED_VALUE"""),530.116743598836) -> 530.11674 | O21: =IFERROR(__xludf.DUMMYFUNCTION("""COMPUTED_VALUE"""),250.299534685029) -> 250.29953
A22: =IFERROR(__xludf.DUMMYFUNCTION("""COMPUTED_VALUE"""),52.0) -> 52 | B22: =IFERROR(__xludf.DUMMYFUNCTION("""COMPUTED_VALUE"""),0.136081472) -> 0.13608147 | C22: =IFERROR(__xludf.DUMMYFUNCTION("""COMPUTED_VALUE"""),0.111351518) -> 0.11135152 | D22: =IFERROR(__xludf.DUMMYFUNCTION("""COMPUTED_VALUE"""),0.149484285) -> 0.14948428 | E22: =IFERROR(__xludf.DUMMYFUNCTION("""COMPUTED_VALUE"""),0.21050375) -> 0.21050375 | F22: =IFERROR(__xludf.DUMMYFUNCTION("""COMPUTED_VALUE"""),0.680533685) -> 0.68053368 | G22: =IFERROR(__xludf.DUMMYFUNCTION("""COMPUTED_VALUE"""),4.821936891) -> 4.8219369 | H22: =IFERROR(__xludf.DUMMYFUNCTION("""COMPUTED_VALUE"""),600000.0) -> 600000 | I22: =IFERROR(__xludf.DUMMYFUNCTION("""COMPUTED_VALUE"""),1000.00121805815) -> 1000.0012 | J22: =IFERROR(__xludf.DUMMYFUNCTION("""COMPUTED_VALUE"""),999.82266553309) -> 999.82267 | K22: =IFERROR(__xludf.DUMMYFUNCTION("""COMPUTED_VALUE"""),1.0) -> 1 | L22: =IFERROR(__xludf.DUMMYFUNCTION("""COMPUTED_VALUE"""),1.98E7) -> 19800000 | M22: =IFERROR(__xludf.DUMMYFUNCTION("""COMPUTED_VALUE"""),0.0355684997916387) -> 0.0355685 | N22: =IFERROR(__xludf.DUMMYFUNCTION("""COMPUTED_VALUE"""),438.110323302534) -> 438.11032 | O22: =IFERROR(__xludf.DUMMYFUNCTION("""COMPUTED_VALUE"""),170.187455649997) -> 170.18746
A23: =IFERROR(__xludf.DUMMYFUNCTION("""COMPUTED_VALUE"""),54.0) -> 54 | B23: =IFERROR(__xludf.DUMMYFUNCTION("""COMPUTED_VALUE"""),0.159285252) -> 0.15928525 | C23: =IFERROR(__xludf.DUMMYFUNCTION("""COMPUTED_VALUE"""),0.110406895) -> 0.1104069 | D23: =IFERROR(__xludf.DUMMYFUNCTION("""COMPUTED_VALUE"""),0.144926147) -> 0.14492615 | E23: =IFERROR(__xludf.DUMMYFUNCTION("""COMPUTED_VALUE"""),0.212635292) -> 0.21263529 | F23: =IFERROR(__xludf.DUMMYFUNCTION("""COMPUTED_VALUE"""),1.535640291) -> 1.5356403 | G23: =IFERROR(__xludf.DUMMYFUNCTION("""COMPUTED_VALUE"""),8.192894382) -> 8.1928944 | H23: =IFERROR(__xludf.DUMMYFUNCTION("""COMPUTED_VALUE"""),600000.0) -> 600000 | I23: =IFERROR(__xludf.DUMMYFUNCTION("""COMPUTED_VALUE"""),1000.00139215027) -> 1000.0014 | J23: =IFERROR(__xludf.DUMMYFUNCTION("""COMPUTED_VALUE"""),999.820974869069) -> 999.82097 | K23: =IFERROR(__xludf.DUMMYFUNCTION("""COMPUTED_VALUE"""),1.0) -> 1 | L23: =IFERROR(__xludf.DUMMYFUNCTION("""COMPUTED_VALUE"""),1.98E7) -> 19800000 | M23: =IFERROR(__xludf.DUMMYFUNCTION("""COMPUTED_VALUE"""),0.0386381379192307) -> 0.038638138 | N23: =IFERROR(__xludf.DUMMYFUNCTION("""COMPUTED_VALUE"""),327.152941611453) -> 327.15294 | O23: =IFERROR(__xludf.DUMMYFUNCTION("""COMPUTED_VALUE"""),93.9656480874392) -> 93.965648
A24: =IFERROR(__xludf.DUMMYFUNCTION("""COMPUTED_VALUE"""),56.0) -> 56 | B24: =IFERROR(__xludf.DUMMYFUNCTION("""COMPUTED_VALUE"""),0.190986245) -> 0.19098624 | C24: =IFERROR(__xludf.DUMMYFUNCTION("""COMPUTED_VALUE"""),0.109860921) -> 0.10986092 | D24: =IFERROR(__xludf.DUMMYFUNCTION("""COMPUTED_VALUE"""),0.136086525) -> 0.13608653 | E24: =IFERROR(__xludf.DUMMYFUNCTION("""COMPUTED_VALUE"""),0.176838361) -> 0.17683836 | F24: =IFERROR(__xludf.DUMMYFUNCTION("""COMPUTED_VALUE"""),2.836587993) -> 2.836588 | G24: =IFERROR(__xludf.DUMMYFUNCTION("""COMPUTED_VALUE"""),17.979167047) -> 17.979167 | H24: =IFERROR(__xludf.DUMMYFUNCTION("""COMPUTED_VALUE"""),600000.0) -> 600000 | I24: =IFERROR(__xludf.DUMMYFUNCTION("""COMPUTED_VALUE"""),1000.00171880128) -> 1000.0017 | J24: =IFERROR(__xludf.DUMMYFUNCTION("""COMPUTED_VALUE"""),999.430439034771) -> 999.43044 | K24: =IFERROR(__xludf.DUMMYFUNCTION("""COMPUTED_VALUE"""),0.999605) -> 0.999605 | L24: =IFERROR(__xludf.DUMMYFUNCTION("""COMPUTED_VALUE"""),1.9792179E7) -> 19792179 | M24: =IFERROR(__xludf.DUMMYFUNCTION("""COMPUTED_VALUE"""),0.0371168920894648) -> 0.037116892 | N24: =IFERROR(__xludf.DUMMYFUNCTION("""COMPUTED_VALUE"""),415.902125427042) -> 415.90213 | O24: =IFERROR(__xludf.DUMMYFUNCTION("""COMPUTED_VALUE"""),98.5333006986931) -> 98.533301
A25: =IFERROR(__xludf.DUMMYFUNCTION("""COMPUTED_VALUE"""),58.0) -> 58 | B25: =IFERROR(__xludf.DUMMYFUNCTION("""COMPUTED_VALUE"""),0.159254364) -> 0.15925436 | C25: =IFERROR(__xludf.DUMMYFUNCTION("""COMPUTED_VALUE"""),0.10862898) -> 0.10862898 | D25: =IFERROR(__xludf.DUMMYFUNCTION("""COMPUTED_VALUE"""),0.122271814) -> 0.12227181 | E25: =IFERROR(__xludf.DUMMYFUNCTION("""COMPUTED_VALUE"""),0.139071188) -> 0.13907119 | F25: =IFERROR(__xludf.DUMMYFUNCTION("""COMPUTED_VALUE"""),1.828304059) -> 1.8283041 | G25: =IFERROR(__xludf.DUMMYFUNCTION("""COMPUTED_VALUE"""),15.874730261) -> 15.87473 | H25: =IFERROR(__xludf.DUMMYFUNCTION("""COMPUTED_VALUE"""),600000.0) -> 600000 | I25: =IFERROR(__xludf.DUMMYFUNCTION("""COMPUTED_VALUE"""),1000.00113270961) -> 1000.0011 | J25: =IFERROR(__xludf.DUMMYFUNCTION("""COMPUTED_VALUE"""),996.297275921096) -> 996.29728 | K25: =IFERROR(__xludf.DUMMYFUNCTION("""COMPUTED_VALUE"""),0.999986666666666) -> 0.99998667 | L25: =IFERROR(__xludf.DUMMYFUNCTION("""COMPUTED_VALUE"""),1.9799736E7) -> 19799736 | M25: =IFERROR(__xludf.DUMMYFUNCTION("""COMPUTED_VALUE"""),0.0356745874416666) -> 0.035674587 | N25: =IFERROR(__xludf.DUMMYFUNCTION("""COMPUTED_VALUE"""),690.165205893619) -> 690.16521 | O25: =IFERROR(__xludf.DUMMYFUNCTION("""COMPUTED_VALUE"""),297.598482529322) -> 297.59848
A26: =IFERROR(__xludf.DUMMYFUNCTION("""COMPUTED_VALUE"""),62.0) -> 62 | B26: =IFERROR(__xludf.DUMMYFUNCTION("""COMPUTED_VALUE"""),0.109934616) -> 0.10993462 | C26: =IFERROR(__xludf.DUMMYFUNCTION("""COMPUTED_VALUE"""),0.108068029) -> 0.10806803 | D26: =IFERROR(__xludf.DUMMYFUNCTION("""COMPUTED_VALUE"""),0.115950292) -> 0.11595029 | E26: =IFERROR(__xludf.DUMMYFUNCTION("""COMPUTED_VALUE"""),0.121063234) -> 0.12106323 | F26: =IFERROR(__xludf.DUMMYFUNCTION("""COMPUTED_VALUE"""),0.13652753) -> 0.13652753 | G26: =IFERROR(__xludf.DUMMYFUNCTION("""COMPUTED_VALUE"""),0.314031549) -> 0.31403155 | H26: =IFERROR(__xludf.DUMMYFUNCTION("""COMPUTED_VALUE"""),600000.0) -> 600000 | I26: =IFERROR(__xludf.DUMMYFUNCTION("""COMPUTED_VALUE"""),1000.00106882447) -> 1000.0011 | J26: =IFERROR(__xludf.DUMMYFUNCTION("""COMPUTED_VALUE"""),999.820826175679) -> 999.82083 | K26: =IFERROR(__xludf.DUMMYFUNCTION("""COMPUTED_VALUE"""),1.0) -> 1 | L26: =IFERROR(__xludf.DUMMYFUNCTION("""COMPUTED_VALUE"""),1.98E7) -> 19800000 | M26: =IFERROR(__xludf.DUMMYFUNCTION("""COMPUTED_VALUE"""),0.0383197498428093) -> 0.03831975 | N26: =IFERROR(__xludf.DUMMYFUNCTION("""COMPUTED_VALUE"""),240.117416195558) -> 240.11742 | O26: =IFERROR(__xludf.DUMMYFUNCTION("""COMPUTED_VALUE"""),54.1990847734827) -> 54.199085
A27: =IFERROR(__xludf.DUMMYFUNCTION("""COMPUTED_VALUE"""),64.0) -> 64 | B27: =IFERROR(__xludf.DUMMYFUNCTION("""COMPUTED_VALUE"""),0.167188239) -> 0.16718824 | C27: =IFERROR(__xludf.DUMMYFUNCTION("""COMPUTED_VALUE"""),0.108658087) -> 0.10865809 | D27: =IFERROR(__xludf.DUMMYFUNCTION("""COMPUTED_VALUE"""),0.13386818) -> 0.13386818 | E27: =IFERROR(__xludf.DUMMYFUNCTION("""COMPUTED_VALUE"""),0.269275051) -> 0.26927505 | F27: =IFERROR(__xludf.DUMMYFUNCTION("""COMPUTED_VALUE"""),1.752252693) -> 1.7522527 | G27: =IFERROR(__xludf.DUMMYFUNCTION("""COMPUTED_VALUE"""),13.296849704) -> 13.29685 | H27: =IFERROR(__xludf.DUMMYFUNCTION("""COMPUTED_VALUE"""),600000.0) -> 600000 | I27: =IFERROR(__xludf.DUMMYFUNCTION("""COMPUTED_VALUE"""),1000.00135930018) -> 1000.0014 | J27: =IFERROR(__xludf.DUMMYFUNCTION("""COMPUTED_VALUE"""),999.815157687565) -> 999.81516 | K27: =IFERROR(__xludf.DUMMYFUNCTION("""COMPUTED_VALUE"""),0.99999) -> 0.99999 | L27: =IFERROR(__xludf.DUMMYFUNCTION("""COMPUTED_VALUE"""),1.9799802E7) -> 19799802 | M27: =IFERROR(__xludf.DUMMYFUNCTION("""COMPUTED_VALUE"""),0.0372727367056856) -> 0.037272737 | N27: =IFERROR(__xludf.DUMMYFUNCTION("""COMPUTED_VALUE"""),422.336021749722) -> 422.33602 | O27: =IFERROR(__xludf.DUMMYFUNCTION("""COMPUTED_VALUE"""),147.218243950828) -> 147.21824
A28: =IFERROR(__xludf.DUMMYFUNCTION("""COMPUTED_VALUE"""),66.0) -> 66 | B28: =IFERROR(__xludf.DUMMYFUNCTION("""COMPUTED_VALUE"""),0.110491713) -> 0.11049171 | C28: =IFERROR(__xludf.DUMMYFUNCTION("""COMPUTED_VALUE"""),0.108359638) -> 0.10835964 | D28: =IFERROR(__xludf.DUMMYFUNCTION("""COMPUTED_VALUE"""),0.11638752) -> 0.11638752 | E28: =IFERROR(__xludf.DUMMYFUNCTION("""COMPUTED_VALUE"""),0.121652307) -> 0.12165231 | F28: =IFERROR(__xludf.DUMMYFUNCTION("""COMPUTED_VALUE"""),0.14085589) -> 0.14085589 | G28: =IFERROR(__xludf.DUMMYFUNCTION("""COMPUTED_VALUE"""),0.446520654) -> 0.44652065 | H28: =IFERROR(__xludf.DUMMYFUNCTION("""COMPUTED_VALUE"""),599999.0) -> 599999 | I28: =IFERROR(__xludf.DUMMYFUNCTION("""COMPUTED_VALUE"""),1000.00012592522) -> 1000.0001 | J28: =IFERROR(__xludf.DUMMYFUNCTION("""COMPUTED_VALUE"""),999.816007187873) -> 999.81601 | K28: =IFERROR(__xludf.DUMMYFUNCTION("""COMPUTED_VALUE"""),1.0) -> 1 | L28: =IFERROR(__xludf.DUMMYFUNCTION("""COMPUTED_VALUE"""),1.9799967E7) -> 19799967 | M28: =IFERROR(__xludf.DUMMYFUNCTION("""COMPUTED_VALUE"""),0.0382900717040133) -> 0.038290072 | N28: =IFERROR(__xludf.DUMMYFUNCTION("""COMPUTED_VALUE"""),252.59217409379) -> 252.59217 | O28: =IFERROR(__xludf.DUMMYFUNCTION("""COMPUTED_VALUE"""),54.7979176495526) -> 54.797918
